Workbook

Sheet กู้
A3: {=SUM(IF(ISNUMBER(Sheet!C2:C21),Sheet!C2:C21,""))} -> 0 | B3: 1 | C3: =MID(Sheet!$A2,7,9) | D3: 11 | E3: =MID(Sheet!$A12,7,9) | F3: {=SUM(IF(ISNUMBER(Sheet!C82:C101),Sheet!C82:C101,""))} -> 0 | G3: 1 | H3: =MID(Sheet!$A82,7,9) | I3: 11 | J3: =MID(Sheet!$A92,7,9)
B4: 2 | C4: =MID(Sheet!A3,7,9) | D4: 12 | E4: =MID(Sheet!$A13,7,9) | G4: 2 | H4: =MID(Sheet!$A83,7,9) | I4: 12 | J4: =MID(Sheet!$A93,7,9)
B5: 3 | C5: =MID(Sheet!A4,7,9) | D5: 13 | E5: =MID(Sheet!$A14,7,9) | G5: 3 | H5: =MID(Sheet!$A84,7,9) | I5: 13 | J5: =MID(Sheet!$A94,7,9)
B6: 4 | C6: =MID(Sheet!A5,7,9) | D6: 14 | E6: =MID(Sheet!$A15,7,9) | G6: 4 | H6: =MID(Sheet!$A85,7,9) | I6: 14 | J6: =MID(Sheet!$A95,7,9)
B7: 5 | C7: =MID(Sheet!A6,7,9) | D7: 15 | E7: =MID(Sheet!$A16,7,9) | G7: 5 | H7: =MID(Sheet!$A86,7,9) | I7: 15 | J7: =MID(Sheet!$A96,7,9)
B8: 6 | C8: =MID(Sheet!A7,7,9) | D8: 16 | E8: =MID(Sheet!$A17,7,9) | G8: 6 | H8: =MID(Sheet!$A87,7,9) | I8: 16 | J8: =MID(Sheet!$A97,7,9)
B9: 7 | C9: =MID(Sheet!A8,7,9) | D9: 17 | E9: =MID(Sheet!$A18,7,9) | G9: 7 | H9: =MID(Sheet!$A88,7,9) | I9: 17 | J9: =MID(Sheet!$A98,7,9)
B10: 8 | C10: =MID(Sheet!A9,7,9) | D10: 18 | E10: =MID(Sheet!$A19,7,9) | G10: 8 | H10: =MID(Sheet!$A89,7,9) | I10: 18 | J10: =MID(Sheet!$A99,7,9)
B11: 9 | C11: =MID(Sheet!A10,7,9) | D11: 19 | E11: =MID(Sheet!$A20,7,9) | G11: 9 | H11: =MID(Sheet!$A90,7,9) | I11: 19 | J11: =MID(Sheet!$A100,7,9)
B12: 10 | C12: =MID(Sheet!A11,7,9) | D12: 20 | E12: =MID(Sheet!$A21,7,9) | G12: 10 | H12: =MID(Sheet!$A91,7,9) | I12: 20 | J12: =MID(Sheet!$A101,7,9)
B13: 2103 มาโนช สมิทธ์พงศ์ธาดา | E13: =COUNTA(Sheet!$A2:$A21) -> 0 | G13: 2103 มาโนช สมิทธ์พงศ์ธาดา | J13: =COUNTA(Sheet!$A82:$A101) -> 0
A17: {=SUM(IF(ISNUMBER(Sheet!C22:C41),Sheet!C22:C41,""))} -> 0 | B17: 1 | C17: =MID(Sheet!$A22,7,9) | D17: 11 | E17: =MID(Sheet!$A32,7,9) | F17: {=SUM(IF(ISNUMBER(Sheet!C102:C121),Sheet!C102:C121,""))} -> 0 | G17: 1 | H17: =MID(Sheet!$A102,7,9) | I17: 11 | J17: =MID(Sheet!$A112,7,9)
B18: 2 | C18: =MID(Sheet!$A23,7,9) | D18: 12 | E18: =MID(Sheet!$A33,7,9) | G18: 2 | H18: =MID(Sheet!$A103,7,9) | I18: 12 | J18: =MID(Sheet!$A113,7,9)
B19: 3 | C19: =MID(Sheet!$A24,7,9) | D19: 13 | E19: =MID(Sheet!$A34,7,9) | G19: 3 | H19: =MID(Sheet!$A104,7,9) | I19: 13 | J19: =MID(Sheet!$A114,7,9)
B20: 4 | C20: =MID(Sheet!$A25,7,9) | D20: 14 | E20: =MID(Sheet!$A35,7,9) | G20: 4 | H20: =MID(Sheet!$A105,7,9) | I20: 14 | J20: =MID(Sheet!$A115,7,9)
B21: 5 | C21: =MID(Sheet!$A26,7,9) | D21: 15 | E21: =MID(Sheet!$A36,7,9) | G21: 5 | H21: =MID(Sheet!$A106,7,9) | I21: 15 | J21: =MID(Sheet!$A116,7,9)
B22: 6 | C22: =MID(Sheet!$A27,7,9) | D22: 16 | E22: =MID(Sheet!$A37,7,9) | G22: 6 | H22: =MID(Sheet!$A107,7,9) | I22: 16 | J22: =MID(Sheet!$A117,7,9)
B23: 7 | C23: =MID(Sheet!$A28,7,9) | D23: 17 | E23: =MID(Sheet!$A38,7,9) | G23: 7 | H23: =MID(Sheet!$A108,7,9) | I23: 17 | J23: =MID(Sheet!$A118,7,9)
B24: 8 | C24: =MID(Sheet!$A29,7,9) | D24: 18 | E24: =MID(Sheet!$A39,7,9) | G24: 8 | H24: =MID(Sheet!$A109,7,9) | I24: 18 | J24: =MID(Sheet!$A119,7,9)
B25: 9 | C25: =MID(Sheet!$A30,7,9) | D25: 19 | E25: =MID(Sheet!$A40,7,9) | G25: 9 | H25: =MID(Sheet!$A110,7,9) | I25: 19 | J25: =MID(Sheet!$A120,7,9)
B26: 10 | C26: =MID(Sheet!$A31,7,9) | D26: 20 | E26: =MID(Sheet!$A41,7,9) | G26: 10 | H26: =MID(Sheet!$A111,7,9) | I26: 20 | J26: =MID(Sheet!$A121,7,9)
B27: 2103 มาโนช สมิทธ์พงศ์ธาดา | E27: =COUNTA(Sheet!A22:A41) -> 0 | G27: 2103 มาโนช สมิทธ์พงศ์ธาดา | J27: =COUNTA(Sheet!$A102:$A121) -> 0
A31: {=SUM(IF(ISNUMBER(Sheet!C42:C61),Sheet!C42:C61,""))} -> 0 | B31: 1 | C31: =MID(Sheet!$A42,7,9) | D31: 11 | E31: =MID(Sheet!$A52,7,9) | F31: {=SUM(IF(ISNUMBER(Sheet!C122:C141),Sheet!C122:C141,""))} -> 0 | G31: 1 | H31: =MID(Sheet!$A122,7,9) | I31: 11 | J31: =MID(Sheet!$A132,7,9)
B32: 2 | C32: =MID(Sheet!$A43,7,9) | D32: 12 | E32: =MID(Sheet!$A53,7,9) | G32: 2 | H32: =MID(Sheet!$A123,7,9) | I32: 12 | J32: =MID(Sheet!$A133,7,9)
B33: 3 | C33: =MID(Sheet!$A44,7,9) | D33: 13 | E33: =MID(Sheet!$A54,7,9) | G33: 3 | H33: =MID(Sheet!$A124,7,9) | I33: 13 | J33: =MID(Sheet!$A134,7,9)
B34: 4 | C34: =MID(Sheet!$A45,7,9) | D34: 14 | E34: =MID(Sheet!$A55,7,9) | G34: 4 | H34: =MID(Sheet!$A125,7,9) | I34: 14 | J34: =MID(Sheet!$A135,7,9)
B35: 5 | C35: =MID(Sheet!$A46,7,9) | D35: 15 | E35: =MID(Sheet!$A56,7,9) | G35: 5 | H35: =MID(Sheet!$A126,7,9) | I35: 15 | J35: =MID(Sheet!$A136,7,9)
B36: 6 | C36: =MID(Sheet!$A47,7,9) | D36: 16 | E36: =MID(Sheet!$A57,7,9) | G36: 6 | H36: =MID(Sheet!$A127,7,9) | I36: 16 | J36: =MID(Sheet!$A137,7,9)
B37: 7 | C37: =MID(Sheet!$A48,7,9) | D37: 17 | E37: =MID(Sheet!$A58,7,9) | G37: 7 | H37: =MID(Sheet!$A128,7,9) | I37: 17 | J37: =MID(Sheet!$A138,7,9)
B38: 8 | C38: =MID(Sheet!$A49,7,9) | D38: 18 | E38: =MID(Sheet!$A59,7,9) | G38: 8 | H38: =MID(Sheet!$A129,7,9) | I38: 18 | J38: =MID(Sheet!$A139,7,9)
B39: p | C39: =MID(Sheet!$A50,7,9) | D39: 19 | E39: =MID(Sheet!$A60,7,9) | G39: 9 | H39: =MID(Sheet!$A130,7,9) | I39: 19 | J39: =MID(Sheet!$A140,7,9)
B40: 10 | C40: =MID(Sheet!$A51,7,9) | D40: 20 | E40: =MID(Sheet!$A61,7,9) | G40: 10 | H40: =MID(Sheet!$A131,7,9) | I40: 20 | J40: =MID(Sheet!$A141,7,9)
B41: 2103 มาโนช สมิทธ์พงศ์ธาดา | E41: =COUNTA(Sheet!A42:A61) -> 0 | G41: 2103 มาโนช สมิทธ์พงศ์ธาดา | J41: =COUNTA(Sheet!$A122:$A141) -> 0
A45: {=SUM(IF(ISNUMBER(Sheet!C62:C81),Sheet!C62:C81,""))} -> 0 | B45: 1 | C45: =MID(Sheet!$A62,7,9) | D45: 11 | E45: =MID(Sheet!$A72,7,9) | F45: {=SUM(IF(ISNUMBER(Sheet!C142:C161),Sheet!C142:C161,""))} -> 0 | G45: 1 | H45: =MID(Sheet!$A142,7,9) | I45: 11 | J45: =MID(Sheet!$A152,7,9)
B46: 2 | C46: =MID(Sheet!$A63,7,9) | D46: 12 | E46: =MID(Sheet!$A73,7,9) | G46: 2 | H46: =MID(Sheet!$A143,7,9) | I46: 12 | J46: =MID(Sheet!$A153,7,9)
B47: 3 | C47: =MID(Sheet!$A64,7,9) | D47: 13 | E47: =MID(Sheet!$A74,7,9) | G47: 3 | H47: =MID(Sheet!$A144,7,9) | I47: 13 | J47: =MID(Sheet!$A154,7,9)
B48: 4 | C48: =MID(Sheet!$A65,7,9) | D48: 14 | E48: =MID(Sheet!$A75,7,9) | G48: 4 | H48: =MID(Sheet!$A145,7,9) | I48: 14 | J48: =MID(Sheet!$A155,7,9)
B49: 5 | C49: =MID(Sheet!$A66,7,9) | D49: 15 | E49: =MID(Sheet!$A76,7,9) | G49: 5 | H49: =MID(Sheet!$A146,7,9) | I49: 15 | J49: =MID(Sheet!$A156,7,9)
B50: 6 | C50: =MID(Sheet!$A67,7,9) | D50: 16 | E50: =MID(Sheet!$A77,7,9) | G50: 6 | H50: =MID(Sheet!$A147,7,9) | I50: 16 | J50: =MID(Sheet!$A157,7,9)
B51: 7 | C51: =MID(Sheet!$A68,7,9) | D51: 17 | E51: =MID(Sheet!$A78,7,9) | G51: 7 | H51: =MID(Sheet!$A148,7,9) | I51: 17 | J51: =MID(Sheet!$A158,7,9)
...

Sheet Sheet
C1: =SUM(C2:C1001) -> 0 | D1: งวด | F1: ปี | H1: วันที่ | I1: เลข | J1: เลข 2 ท้าย | K1: เลข 3 หน้า | L1: เลข 3 หลัง | M1: 2 ท้าย | N1: 3 หน้า | O1: 3 หลัง | P1: ที่ 1 | Q1: ข้างเคียง | R1: ที่ 2 | S1: ที่ 3 | T1: ที่ 4 | U1: ที่ 5 | V1: อายัด | X1: A1 | Y1: 2 ท้าย | Z1: 3 หน้า | AA1: 3 หลัง | AB1: ที่ 1 | AC1: ข้างเคียง | AD1: ที่ 2 | AE1: ที่ 3 | AF1: ที่ 4 | AG1: ที่ 5 | AH1: ปี | AI1: อายัด | AJ1: % | AL1: =SUM(AL2:AL1000) -> 0 | AM1: Time | AN1: หน้า | AO1: หลัง | AP1: อายัด
B2: =LEFT(A2,15) | C2: {=SUM(IF(ISNUMBER(M2:W2),M2:W2,""))} -> 0 | D2: =MID(B2,4,2) | E2: =IF(ISEVEN(D2),D2-1,VALUE(D2)) -> #VALUE! | F2: =LEFT(B2,2) | G2: =CONCATENATE(F2,".xlsx") -> .xlsx | H2: {=IF(AND(VALUE(E2)=INDIRECT("'["&G2&"]"&E2&"'!"&$X$2),G2=INDIRECT("'["&G2&"]"&E2&"'!"&$X$3)),INDIRECT("'["&G2&"]"&E2&"'!"&$X$1),0)} -> #VALUE! | I2: =MID(B2,10,6) | J2: =RIGHT(I2,2) | K2: =LEFT(I2,3) | L2: =RIGHT(I2,3) | M2: {=IF(AND(J2=INDIRECT("'["&G2&"]"&E2&"'!"&$Y$2),G2=INDIRECT("'["&G2&"]"&E2&"'!"&$AH$2)),INDIRECT("'["&G2&"]"&E2&"'!"&$Y$3),0)} -> #VALUE! | N2: {=IF(AND(G2=INDIRECT("'["&G2&"]"&E2&"'!"&$AH$2),OR(K2=INDIRECT("'["&G2&"]"&E2&"'!"&$Z$2))),INDIRECT("'["&G2&"]"&E2&"'!"&$Z$3),0)} -> #VALUE! | O2: {=IF(AND(G2=INDIRECT("'["&G2&"]"&E2&"'!"&$AH$2),OR(L2=INDIRECT("'["&G2&"]"&E2&"'!"&$AA$2))),INDIRECT("'["&G2&"]"&E2&"'!"&$AA$3),0)} -> #VALUE! | P2: {=IF(AND(G2=INDIRECT("'["&G2&"]"&E2&"'!"&$AH$2),OR(VALUE(I2)=INDIRECT("'["&G2&"]"&E2&"'!"&$AB$2))),INDIRECT("'["&G2&"]"&E2&"'!"&$AB$3),0)} -> #VALUE! | Q2: {=IF(AND(G2=INDIRECT("'["&G2&"]"&E2&"'!"&$AH$2),OR(VALUE(I2)=INDIRECT("'["&G2&"]"&E2&"'!"&$AC$2))),INDIRECT("'["&G2&"]"&E2&"'!"&$AC$3),0)} -> #VALUE! | R2: {=IF(AND(G2=INDIRECT("'["&G2&"]"&E2&"'!"&$AH$2),OR(I2=INDIRECT("'["&G2&"]"&E2&"'!"&$AD$2))),INDIRECT("'["&G2&"]"&E2&"'!"&$AD$3),0)} -> #VALUE! | S2: {=IF(AND(G2=INDIRECT("'["&G2&"]"&E2&"'!"&$AH$2),OR(I2=INDIRECT("'["&G2&"]"&E2&"'!"&$AE$2))),INDIRECT("'["&G2&"]"&E2&"'!"&$AE$3),0)} -> #VALUE! | T2: {=IF(AND(G2=INDIRECT("'["&G2&"]"&E2&"'!"&$AH$2),OR(I2=INDIRECT("'["&G2&"]"&E2&"'!"&$AF$2))),INDIRECT("'["&G2&"]"&E2&"'!"&$AF$3),0)} -> #VALUE! | U2: {=IF(AND(G2=INDIRECT("'["&G2&"]"&E2&"'!"&$AH$2),OR(I2=INDIRECT("'["&G2&"]"&E2&"'!"&$AG$2))),INDIRECT("'["&G2&"]"&E2&"'!"&$AG$3),0)} -> #VALUE! | V2: =MID(B2,7,9) | W2: {=IF(AND(G2=INDIRECT("'["&G2&"]"&E2&"'!"&$AH$2),OR(V2=INDIRECT("'["&G2&"]"&E2&"'!"&$AI$2))),INDIRECT("'["&G2&"]"&E2&"'!"&$AI$3),0)} -> #VALUE! | X2: A2 | Y2: B4 | Z2: B5:C5 | AA2: B6:C6 | AB2: B7 | AC2: B8:C8 | AD2: B9:F9 | AE2: B10:K10 | AF2: B11:K15 | AG2: B16:K25 | AH2: B2 | AI2: B26:K115 | AJ2: 1 | AK2: =(C2*AJ2%) -> 0 | AL2: =C2-AK2 -> 0 | AM2: =IF(A2<>"",IF(AM2="",NOW(),AM2),"") | AN2: =IF(VALUE(N2),"/","") -> #VALUE! | AO2: =IF(VALUE(O2),"/","") -> #VALUE! | AP2: =IF(ISTEXT(W2),"อายัด","") | AQ2: =IF(AND(C2<>0, C3=0), SUM($C$2:C2)-SUM($AQ$1:AQ1), "") | AR2: =IF(AND(AK2<>0, AK3=0), SUM($AK$2:AK2)-SUM($AR$1:AR1), "")
B3: =LEFT(A3,15) | C3: {=SUM(IF(ISNUMBER(M3:U3),M3:U3,""))} -> 0 | D3: =MID(A3,4,2) | E3: =IF(ISEVEN(D3),D3-1,VALUE(D3)) -> #VALUE! | F3: =LEFT(A3,2) | G3: =CONCATENATE(F3,".xlsx") -> .xlsx | H3: {=IF(AND(VALUE(E3)=INDIRECT("'["&G3&"]"&E3&"'!"&$X$2),G3=INDIRECT("'["&G3&"]"&E3&"'!"&$X$3)),INDIRECT("'["&G3&"]"&E3&"'!"&$X$1),0)} -> #VALUE! | I3: =MID(A3,10,6) | J3: =RIGHT(I3,2) | K3: =LEFT(I3,3) | L3: =RIGHT(I3,3) | M3: {=IF(AND(J3=INDIRECT("'["&G3&"]"&E3&"'!"&$Y$2),G3=INDIRECT("'["&G3&"]"&E3&"'!"&$AH$2)),INDIRECT("'["&G3&"]"&E3&"'!"&$Y$3),0)} -> #VALUE! | N3: {=IF(AND(G3=INDIRECT("'["&G3&"]"&E3&"'!"&$AH$2),OR(K3=INDIRECT("'["&G3&"]"&E3&"'!"&$Z$2))),INDIRECT("'["&G3&"]"&E3&"'!"&$Z$3),0)} -> #VALUE! | O3: {=IF(AND(G3=INDIRECT("'["&G3&"]"&E3&"'!"&$AH$2),OR(L3=INDIRECT("'["&G3&"]"&E3&"'!"&$AA$2))),INDIRECT("'["&G3&"]"&E3&"'!"&$AA$3),0)} -> #VALUE! | P3: {=IF(AND(G3=INDIRECT("'["&G3&"]"&E3&"'!"&$AH$2),OR(VALUE(I3)=INDIRECT("'["&G3&"]"&E3&"'!"&$AB$2))),INDIRECT("'["&G3&"]"&E3&"'!"&$AB$3),0)} -> #VALUE! | Q3: {=IF(AND(G3=INDIRECT("'["&G3&"]"&E3&"'!"&$AH$2),OR(VALUE(I3)=INDIRECT("'["&G3&"]"&E3&"'!"&$AC$2))),INDIRECT("'["&G3&"]"&E3&"'!"&$AC$3),0)} -> #VALUE! | R3: {=IF(AND(G3=INDIRECT("'["&G3&"]"&E3&"'!"&$AH$2),OR(I3=INDIRECT("'["&G3&"]"&E3&"'!"&$AD$2))),INDIRECT("'["&G3&"]"&E3&"'!"&$AD$3),0)} -> #VALUE! | S3: {=IF(AND(G3=INDIRECT("'["&G3&"]"&E3&"'!"&$AH$2),OR(I3=INDIRECT("'["&G3&"]"&E3&"'!"&$AE$2))),INDIRECT("'["&G3&"]"&E3&"'!"&$AE$3),0)} -> #VALUE! | T3: {=IF(AND(G3=INDIRECT("'["&G3&"]"&E3&"'!"&$AH$2),OR(I3=INDIRECT("'["&G3&"]"&E3&"'!"&$AF$2))),INDIRECT("'["&G3&"]"&E3&"'!"&$AF$3),0)} -> #VALUE! | U3: {=IF(AND(G3=INDIRECT("'["&G3&"]"&E3&"'!"&$AH$2),OR(I3=INDIRECT("'["&G3&"]"&E3&"'!"&$AG$2))),INDIRECT("'["&G3&"]"&E3&"'!"&$AG$3),0)} -> #VALUE! | V3: =MID(B3,7,9) | W3: {=IF(AND(G3=INDIRECT("'["&G3&"]"&E3&"'!"&$AH$2),OR(V3=INDIRECT("'["&G3&"]"&E3&"'!"&$AI$2))),INDIRECT("'["&G3&"]"&E3&"'!"&$AI$3),0)} -> #VALUE! | X3: B2 | Y3: l4 | Z3: L5 | AA3: L6 | AB3: L7 | AC3: L8 | AD3: L9 | AE3: L10 | AF3: L11 | AG3: L16 | AI3: L26 | AJ3: 1 | AK3: =(C3*AJ3%) -> 0 | AL3: =C3-AK3 -> 0 | AM3: =IF(A3<>"",IF(AM3="",NOW(),AM3),"") | AN3: =IF(VALUE(N3),"/","") -> #VALUE! | AO3: =IF(VALUE(O3),"/","") -> #VALUE! | AP3: =IF(ISTEXT(W3),"อายัด","") | AQ3: =IF(AND(C3<>0, C4=0), SUM($C$2:C3)-SUM($AQ$1:AQ2), "") | AR3: =IF(AND(AK3<>0, AK4=0), SUM($AK$2:AK3)-SUM($AR$1:AR2), "")
B4: =LEFT(A4,15) | C4: {=SUM(IF(ISNUMBER(M4:U4),M4:U4,""))} -> 0 | D4: =MID(A4,4,2) | E4: =IF(ISEVEN(D4),D4-1,VALUE(D4)) -> #VALUE! | F4: =LEFT(A4,2) | G4: =CONCATENATE(F4,".xlsx") -> .xlsx | H4: {=IF(AND(VALUE(E4)=INDIRECT("'["&G4&"]"&E4&"'!"&$X$2),G4=INDIRECT("'["&G4&"]"&E4&"'!"&$X$3)),INDIRECT("'["&G4&"]"&E4&"'!"&$X$1),0)} -> #VALUE! | I4: =MID(A4,10,6) | J4: =RIGHT(I4,2) | K4: =LEFT(I4,3) | L4: =RIGHT(I4,3) | M4: {=IF(AND(J4=INDIRECT("'["&G4&"]"&E4&"'!"&$Y$2),G4=INDIRECT("'["&G4&"]"&E4&"'!"&$AH$2)),INDIRECT("'["&G4&"]"&E4&"'!"&$Y$3),0)} -> #VALUE! | N4: {=IF(AND(G4=INDIRECT("'["&G4&"]"&E4&"'!"&$AH$2),OR(K4=INDIRECT("'["&G4&"]"&E4&"'!"&$Z$2))),INDIRECT("'["&G4&"]"&E4&"'!"&$Z$3),0)} -> #VALUE! | O4: {=IF(AND(G4=INDIRECT("'["&G4&"]"&E4&"'!"&$AH$2),OR(L4=INDIRECT("'["&G4&"]"&E4&"'!"&$AA$2))),INDIRECT("'["&G4&"]"&E4&"'!"&$AA$3),0)} -> #VALUE! | P4: {=IF(AND(G4=INDIRECT("'["&G4&"]"&E4&"'!"&$AH$2),OR(VALUE(I4)=INDIRECT("'["&G4&"]"&E4&"'!"&$AB$2))),INDIRECT("'["&G4&"]"&E4&"'!"&$AB$3),0)} -> #VALUE! | Q4: {=IF(AND(G4=INDIRECT("'["&G4&"]"&E4&"'!"&$AH$2),OR(VALUE(I4)=INDIRECT("'["&G4&"]"&E4&"'!"&$AC$2))),INDIRECT("'["&G4&"]"&E4&"'!"&$AC$3),0)} -> #VALUE! | R4: {=IF(AND(G4=INDIRECT("'["&G4&"]"&E4&"'!"&$AH$2),OR(I4=INDIRECT("'["&G4&"]"&E4&"'!"&$AD$2))),INDIRECT("'["&G4&"]"&E4&"'!"&$AD$3),0)} -> #VALUE! | S4: {=IF(AND(G4=INDIRECT("'["&G4&"]"&E4&"'!"&$AH$2),OR(I4=INDIRECT("'["&G4&"]"&E4&"'!"&$AE$2))),INDIRECT("'["&G4&"]"&E4&"'!"&$AE$3),0)} -> #VALUE! | T4: {=IF(AND(G4=INDIRECT("'["&G4&"]"&E4&"'!"&$AH$2),OR(I4=INDIRECT("'["&G4&"]"&E4&"'!"&$AF$2))),INDIRECT("'["&G4&"]"&E4&"'!"&$AF$3),0)} -> #VALUE! | U4: {=IF(AND(G4=INDIRECT("'["&G4&"]"&E4&"'!"&$AH$2),OR(I4=INDIRECT("'["&G4&"]"&E4&"'!"&$AG$2))),INDIRECT("'["&G4&"]"&E4&"'!"&$AG$3),0)} -> #VALUE! | V4: =MID(B4,7,9) | W4: {=IF(AND(G4=INDIRECT("'["&G4&"]"&E4&"'!"&$AH$2),OR(V4=INDIRECT("'["&G4&"]"&E4&"'!"&$AI$2))),INDIRECT("'["&G4&"]"&E4&"'!"&$AI$3),0)} -> #VALUE! | AJ4: 1 | AK4: =(C4*AJ4%) -> 0 | AL4: =C4-AK4 -> 0 | AM4: =IF(A4<>"",IF(AM4="",NOW(),AM4),"") | AN4: =IF(VALUE(N4),"/","") -> #VALUE! | AO4: =IF(VALUE(O4),"/","") -> #VALUE! | AP4: =IF(ISTEXT(W4),"อายัด","") | AQ4: =IF(AND(C4<>0, C5=0), SUM($C$2:C4)-SUM($AQ$1:AQ3), "") | AR4: =IF(AND(AK4<>0, AK5=0), SUM($AK$2:AK4)-SUM($AR$1:AR3), "")
B5: =LEFT(A5,15) | C5: {=SUM(IF(ISNUMBER(M5:U5),M5:U5,""))} -> 0 | D5: =MID(A5,4,2) | E5: =IF(ISEVEN(D5),D5-1,VALUE(D5)) -> #VALUE! | F5: =LEFT(A5,2) | G5: =CONCATENATE(F5,".xlsx") -> .xlsx | H5: {=IF(AND(VALUE(E5)=INDIRECT("'["&G5&"]"&E5&"'!"&$X$2),G5=INDIRECT("'["&G5&"]"&E5&"'!"&$X$3)),INDIRECT("'["&G5&"]"&E5&"'!"&$X$1),0)} -> #VALUE! | I5: =MID(A5,10,6) | J5: =RIGHT(I5,2) | K5: =LEFT(I5,3) | L5: =RIGHT(I5,3) | M5: {=IF(AND(J5=INDIRECT("'["&G5&"]"&E5&"'!"&$Y$2),G5=INDIRECT("'["&G5&"]"&E5&"'!"&$AH$2)),INDIRECT("'["&G5&"]"&E5&"'!"&$Y$3),"")} -> #VALUE! | N5: {=IF(AND(G5=INDIRECT("'["&G5&"]"&E5&"'!"&$AH$2),OR(K5=INDIRECT("'["&G5&"]"&E5&"'!"&$Z$2))),INDIRECT("'["&G5&"]"&E5&"'!"&$Z$3),0)} -> #VALUE! | O5: {=IF(AND(G5=INDIRECT("'["&G5&"]"&E5&"'!"&$AH$2),OR(L5=INDIRECT("'["&G5&"]"&E5&"'!"&$AA$2))),INDIRECT("'["&G5&"]"&E5&"'!"&$AA$3),0)} -> #VALUE! | P5: {=IF(AND(G5=INDIRECT("'["&G5&"]"&E5&"'!"&$AH$2),OR(VALUE(I5)=INDIRECT("'["&G5&"]"&E5&"'!"&$AB$2))),INDIRECT("'["&G5&"]"&E5&"'!"&$AB$3),0)} -> #VALUE! | Q5: {=IF(AND(G5=INDIRECT("'["&G5&"]"&E5&"'!"&$AH$2),OR(VALUE(I5)=INDIRECT("'["&G5&"]"&E5&"'!"&$AC$2))),INDIRECT("'["&G5&"]"&E5&"'!"&$AC$3),0)} -> #VALUE! | R5: {=IF(AND(G5=INDIRECT("'["&G5&"]"&E5&"'!"&$AH$2),OR(I5=INDIRECT("'["&G5&"]"&E5&"'!"&$AD$2))),INDIRECT("'["&G5&"]"&E5&"'!"&$AD$3),0)} -> #VALUE! | S5: {=IF(AND(G5=INDIRECT("'["&G5&"]"&E5&"'!"&$AH$2),OR(I5=INDIRECT("'["&G5&"]"&E5&"'!"&$AE$2))),INDIRECT("'["&G5&"]"&E5&"'!"&$AE$3),0)} -> #VALUE! | T5: {=IF(AND(G5=INDIRECT("'["&G5&"]"&E5&"'!"&$AH$2),OR(I5=INDIRECT("'["&G5&"]"&E5&"'!"&$AF$2))),INDIRECT("'["&G5&"]"&E5&"'!"&$AF$3),0)} -> #VALUE! | U5: {=IF(AND(G5=INDIRECT("'["&G5&"]"&E5&"'!"&$AH$2),OR(I5=INDIRECT("'["&G5&"]"&E5&"'!"&$AG$2))),INDIRECT("'["&G5&"]"&E5&"'!"&$AG$3),0)} -> #VALUE! | V5: =MID(B5,7,9) | W5: {=IF(AND(G5=INDIRECT("'["&G5&"]"&E5&"'!"&$AH$2),OR(V5=INDIRECT("'["&G5&"]"&E5&"'!"&$AI$2))),INDIRECT("'["&G5&"]"&E5&"'!"&$AI$3),0)} -> #VALUE! | AJ5: 1 | AK5: =(C5*AJ5%) -> 0 | AL5: =C5-AK5 -> 0 | AM5: =IF(A5<>"",IF(AM5="",NOW(),AM5),"") | AN5: =IF(VALUE(N5),"/","") -> #VALUE! | AO5: =IF(VALUE(O5),"/","") -> #VALUE! | AP5: =IF(ISTEXT(W5),"อายัด","") | AQ5: =IF(AND(C5<>0, C6=0), SUM($C$2:C5)-SUM($AQ$1:AQ4), "") | AR5: =IF(AND(AK5<>0, AK6=0), SUM($AK$2:AK5)-SUM($AR$1:AR4), "")
B6: =LEFT(A6,15) | C6: {=SUM(IF(ISNUMBER(M6:U6),M6:U6,""))} -> 0 | D6: =MID(A6,4,2) | E6: =IF(ISEVEN(D6),D6-1,VALUE(D6)) -> #VALUE! | F6: =LEFT(A6,2) | G6: =CONCATENATE(F6,".xlsx") -> .xlsx | H6: {=IF(AND(VALUE(E6)=INDIRECT("'["&G6&"]"&E6&"'!"&$X$2),G6=INDIRECT("'["&G6&"]"&E6&"'!"&$X$3)),INDIRECT("'["&G6&"]"&E6&"'!"&$X$1),0)} -> #VALUE! | I6: =MID(A6,10,6) | J6: =RIGHT(I6,2) | K6: =LEFT(I6,3) | L6: =RIGHT(I6,3) | M6: {=IF(AND(J6=INDIRECT("'["&G6&"]"&E6&"'!"&$Y$2),G6=INDIRECT("'["&G6&"]"&E6&"'!"&$AH$2)),INDIRECT("'["&G6&"]"&E6&"'!"&$Y$3),0)} -> #VALUE! | N6: {=IF(AND(G6=INDIRECT("'["&G6&"]"&E6&"'!"&$AH$2),OR(K6=INDIRECT("'["&G6&"]"&E6&"'!"&$Z$2))),INDIRECT("'["&G6&"]"&E6&"'!"&$Z$3),0)} -> #VALUE! | O6: {=IF(AND(G6=INDIRECT("'["&G6&"]"&E6&"'!"&$AH$2),OR(L6=INDIRECT("'["&G6&"]"&E6&"'!"&$AA$2))),INDIRECT("'["&G6&"]"&E6&"'!"&$AA$3),0)} -> #VALUE! | P6: {=IF(AND(G6=INDIRECT("'["&G6&"]"&E6&"'!"&$AH$2),OR(VALUE(I6)=INDIRECT("'["&G6&"]"&E6&"'!"&$AB$2))),INDIRECT("'["&G6&"]"&E6&"'!"&$AB$3),0)} -> #VALUE! | Q6: {=IF(AND(G6=INDIRECT("'["&G6&"]"&E6&"'!"&$AH$2),OR(VALUE(I6)=INDIRECT("'["&G6&"]"&E6&"'!"&$AC$2))),INDIRECT("'["&G6&"]"&E6&"'!"&$AC$3),0)} -> #VALUE! | R6: {=IF(AND(G6=INDIRECT("'["&G6&"]"&E6&"'!"&$AH$2),OR(I6=INDIRECT("'["&G6&"]"&E6&"'!"&$AD$2))),INDIRECT("'["&G6&"]"&E6&"'!"&$AD$3),0)} -> #VALUE! | S6: {=IF(AND(G6=INDIRECT("'["&G6&"]"&E6&"'!"&$AH$2),OR(I6=INDIRECT("'["&G6&"]"&E6&"'!"&$AE$2))),INDIRECT("'["&G6&"]"&E6&"'!"&$AE$3),0)} -> #VALUE! | T6: {=IF(AND(G6=INDIRECT("'["&G6&"]"&E6&"'!"&$AH$2),OR(I6=INDIRECT("'["&G6&"]"&E6&"'!"&$AF$2))),INDIRECT("'["&G6&"]"&E6&"'!"&$AF$3),0)} -> #VALUE! | U6: {=IF(AND(G6=INDIRECT("'["&G6&"]"&E6&"'!"&$AH$2),OR(I6=INDIRECT("'["&G6&"]"&E6&"'!"&$AG$2))),INDIRECT("'["&G6&"]"&E6&"'!"&$AG$3),0)} -> #VALUE! | V6: =MID(B6,7,9) | W6: {=IF(AND(G6=INDIRECT("'["&G6&"]"&E6&"'!"&$AH$2),OR(V6=INDIRECT("'["&G6&"]"&E6&"'!"&$AI$2))),INDIRECT("'["&G6&"]"&E6&"'!"&$AI$3),0)} -> #VALUE! | AJ6: 1 | AK6: =(C6*AJ6%) -> 0 | AL6: =C6-AK6 -> 0 | AM6: =IF(A6<>"",IF(AM6="",NOW(),AM6),"") | AN6: =IF(VALUE(N6),"/","") -> #VALUE! | AO6: =IF(VALUE(O6),"/","") -> #VALUE! | AP6: =IF(ISTEXT(W6),"อายัด","") | AQ6: =IF(AND(C6<>0, C7=0), SUM($C$2:C6)-SUM($AQ$1:AQ5), "") | AR6: =IF(AND(AK6<>0, AK7=0), SUM($AK$2:AK6)-SUM($AR$1:AR5), "")
B7: =LEFT(A7,15) | C7: {=SUM(IF(ISNUMBER(M7:U7),M7:U7,""))} -> 0 | D7: =MID(A7,4,2) | E7: =IF(ISEVEN(D7),D7-1,VALUE(D7)) -> #VALUE! | F7: =LEFT(A7,2) | G7: =CONCATENATE(F7,".xlsx") -> .xlsx | H7: {=IF(AND(VALUE(E7)=INDIRECT("'["&G7&"]"&E7&"'!"&$X$2),G7=INDIRECT("'["&G7&"]"&E7&"'!"&$X$3)),INDIRECT("'["&G7&"]"&E7&"'!"&$X$1),0)} -> #VALUE! | I7: =MID(A7,10,6) | J7: =RIGHT(I7,2) | K7: =LEFT(I7,3) | L7: =RIGHT(I7,3) | M7: {=IF(AND(J7=INDIRECT("'["&G7&"]"&E7&"'!"&$Y$2),G7=INDIRECT("'["&G7&"]"&E7&"'!"&$AH$2)),INDIRECT("'["&G7&"]"&E7&"'!"&$Y$3),0)} -> #VALUE! | N7: {=IF(AND(G7=INDIRECT("'["&G7&"]"&E7&"'!"&$AH$2),OR(K7=INDIRECT("'["&G7&"]"&E7&"'!"&$Z$2))),INDIRECT("'["&G7&"]"&E7&"'!"&$Z$3),0)} -> #VALUE! | O7: {=IF(AND(G7=INDIRECT("'["&G7&"]"&E7&"'!"&$AH$2),OR(L7=INDIRECT("'["&G7&"]"&E7&"'!"&$AA$2))),INDIRECT("'["&G7&"]"&E7&"'!"&$AA$3),0)} -> #VALUE! | P7: {=IF(AND(G7=INDIRECT("'["&G7&"]"&E7&"'!"&$AH$2),OR(VALUE(I7)=INDIRECT("'["&G7&"]"&E7&"'!"&$AB$2))),INDIRECT("'["&G7&"]"&E7&"'!"&$AB$3),0)} -> #VALUE! | Q7: {=IF(AND(G7=INDIRECT("'["&G7&"]"&E7&"'!"&$AH$2),OR(VALUE(I7)=INDIRECT("'["&G7&"]"&E7&"'!"&$AC$2))),INDIRECT("'["&G7&"]"&E7&"'!"&$AC$3),0)} -> #VALUE! | R7: {=IF(AND(G7=INDIRECT("'["&G7&"]"&E7&"'!"&$AH$2),OR(I7=INDIRECT("'["&G7&"]"&E7&"'!"&$AD$2))),INDIRECT("'["&G7&"]"&E7&"'!"&$AD$3),0)} -> #VALUE! | S7: {=IF(AND(G7=INDIRECT("'["&G7&"]"&E7&"'!"&$AH$2),OR(I7=INDIRECT("'["&G7&"]"&E7&"'!"&$AE$2))),INDIRECT("'["&G7&"]"&E7&"'!"&$AE$3),0)} -> #VALUE! | T7: {=IF(AND(G7=INDIRECT("'["&G7&"]"&E7&"'!"&$AH$2),OR(I7=INDIRECT("'["&G7&"]"&E7&"'!"&$AF$2))),INDIRECT("'["&G7&"]"&E7&"'!"&$AF$3),0)} -> #VALUE! | U7: {=IF(AND(G7=INDIRECT("'["&G7&"]"&E7&"'!"&$AH$2),OR(I7=INDIRECT("'["&G7&"]"&E7&"'!"&$AG$2))),INDIRECT("'["&G7&"]"&E7&"'!"&$AG$3),0)} -> #VALUE! | V7: =MID(B7,7,9) | W7: {=IF(AND(G7=INDIRECT("'["&G7&"]"&E7&"'!"&$AH$2),OR(V7=INDIRECT("'["&G7&"]"&E7&"'!"&$AI$2))),INDIRECT("'["&G7&"]"&E7&"'!"&$AI$3),0)} -> #VALUE! | AJ7: 1 | AK7: =(C7*AJ7%) -> 0 | AL7: =C7-AK7 -> 0 | AM7: =IF(A7<>"",IF(AM7="",NOW(),AM7),"") | AN7: =IF(VALUE(N7),"/","") -> #VALUE! | AO7: =IF(VALUE(O7),"/","") -> #VALUE! | AP7: =IF(ISTEXT(W7),"อายัด","") | AQ7: =IF(AND(C7<>0, C8=0), SUM($C$2:C7)-SUM($AQ$1:AQ6), "") | AR7: =IF(AND(AK7<>0, AK8=0), SUM($AK$2:AK7)-SUM($AR$1:AR6), "")
B8: =LEFT(A8,15) | C8: {=SUM(IF(ISNUMBER(M8:U8),M8:U8,""))} -> 0 | D8: =MID(A8,4,2) | E8: =IF(ISEVEN(D8),D8-1,VALUE(D8)) -> #VALUE! | F8: =LEFT(A8,2) | G8: =CONCATENATE(F8,".xlsx") -> .xlsx | H8: {=IF(AND(VALUE(E8)=INDIRECT("'["&G8&"]"&E8&"'!"&$X$2),G8=INDIRECT("'["&G8&"]"&E8&"'!"&$X$3)),INDIRECT("'["&G8&"]"&E8&"'!"&$X$1),0)} -> #VALUE! | I8: =MID(A8,10,6) | J8: =RIGHT(I8,2) | K8: =LEFT(I8,3) | L8: =RIGHT(I8,3) | M8: {=IF(AND(J8=INDIRECT("'["&G8&"]"&E8&"'!"&$Y$2),G8=INDIRECT("'["&G8&"]"&E8&"'!"&$AH$2)),INDIRECT("'["&G8&"]"&E8&"'!"&$Y$3),0)} -> #VALUE! | N8: {=IF(AND(G8=INDIRECT("'["&G8&"]"&E8&"'!"&$AH$2),OR(K8=INDIRECT("'["&G8&"]"&E8&"'!"&$Z$2))),INDIRECT("'["&G8&"]"&E8&"'!"&$Z$3),0)} -> #VALUE! | O8: {=IF(AND(G8=INDIRECT("'["&G8&"]"&E8&"'!"&$AH$2),OR(L8=INDIRECT("'["&G8&"]"&E8&"'!"&$AA$2))),INDIRECT("'["&G8&"]"&E8&"'!"&$AA$3),0)} -> #VALUE! | P8: {=IF(AND(G8=INDIRECT("'["&G8&"]"&E8&"'!"&$AH$2),OR(VALUE(I8)=INDIRECT("'["&G8&"]"&E8&"'!"&$AB$2))),INDIRECT("'["&G8&"]"&E8&"'!"&$AB$3),0)} -> #VALUE! | Q8: {=IF(AND(G8=INDIRECT("'["&G8&"]"&E8&"'!"&$AH$2),OR(VALUE(I8)=INDIRECT("'["&G8&"]"&E8&"'!"&$AC$2))),INDIRECT("'["&G8&"]"&E8&"'!"&$AC$3),0)} -> #VALUE! | R8: {=IF(AND(G8=INDIRECT("'["&G8&"]"&E8&"'!"&$AH$2),OR(I8=INDIRECT("'["&G8&"]"&E8&"'!"&$AD$2))),INDIRECT("'["&G8&"]"&E8&"'!"&$AD$3),0)} -> #VALUE! | S8: {=IF(AND(G8=INDIRECT("'["&G8&"]"&E8&"'!"&$AH$2),OR(I8=INDIRECT("'["&G8&"]"&E8&"'!"&$AE$2))),INDIRECT("'["&G8&"]"&E8&"'!"&$AE$3),0)} -> #VALUE! | T8: {=IF(AND(G8=INDIRECT("'["&G8&"]"&E8&"'!"&$AH$2),OR(I8=INDIRECT("'["&G8&"]"&E8&"'!"&$AF$2))),INDIRECT("'["&G8&"]"&E8&"'!"&$AF$3),0)} -> #VALUE! | U8: {=IF(AND(G8=INDIRECT("'["&G8&"]"&E8&"'!"&$AH$2),OR(I8=INDIRECT("'["&G8&"]"&E8&"'!"&$AG$2))),INDIRECT("'["&G8&"]"&E8&"'!"&$AG$3),0)} -> #VALUE! | V8: =MID(B8,7,9) | W8: {=IF(AND(G8=INDIRECT("'["&G8&"]"&E8&"'!"&$AH$2),OR(V8=INDIRECT("'["&G8&"]"&E8&"'!"&$AI$2))),INDIRECT("'["&G8&"]"&E8&"'!"&$AI$3),0)} -> #VALUE! | AJ8: 1 | AK8: =(C8*AJ8%) -> 0 | AL8: =C8-AK8 -> 0 | AM8: =IF(A8<>"",IF(AM8="",NOW(),AM8),"") | AN8: =IF(VALUE(N8),"/","") -> #VALUE! | AO8: =IF(VALUE(O8),"/","") -> #VALUE! | AP8: =IF(ISTEXT(W8),"อายัด","") | AQ8: =IF(AND(C8<>0, C9=0), SUM($C$2:C8)-SUM($AQ$1:AQ7), "") | AR8: =IF(AND(AK8<>0, AK9=0), SUM($AK$2:AK8)-SUM($AR$1:AR7), "")
B9: =LEFT(A9,15) | C9: {=SUM(IF(ISNUMBER(M9:U9),M9:U9,""))} -> 0 | D9: =MID(A9,4,2) | E9: =IF(ISEVEN(D9),D9-1,VALUE(D9)) -> #VALUE! | F9: =LEFT(A9,2) | G9: =CONCATENATE(F9,".xlsx") -> .xlsx | H9: {=IF(AND(VALUE(E9)=INDIRECT("'["&G9&"]"&E9&"'!"&$X$2),G9=INDIRECT("'["&G9&"]"&E9&"'!"&$X$3)),INDIRECT("'["&G9&"]"&E9&"'!"&$X$1),0)} -> #VALUE! | I9: =MID(A9,10,6) | J9: =RIGHT(I9,2) | K9: =LEFT(I9,3) | L9: =RIGHT(I9,3) | M9: {=IF(AND(J9=INDIRECT("'["&G9&"]"&E9&"'!"&$Y$2),G9=INDIRECT("'["&G9&"]"&E9&"'!"&$AH$2)),INDIRECT("'["&G9&"]"&E9&"'!"&$Y$3),0)} -> #VALUE! | N9: {=IF(AND(G9=INDIRECT("'["&G9&"]"&E9&"'!"&$AH$2),OR(K9=INDIRECT("'["&G9&"]"&E9&"'!"&$Z$2))),INDIRECT("'["&G9&"]"&E9&"'!"&$Z$3),0)} -> #VALUE! | O9: {=IF(AND(G9=INDIRECT("'["&G9&"]"&E9&"'!"&$AH$2),OR(L9=INDIRECT("'["&G9&"]"&E9&"'!"&$AA$2))),INDIRECT("'["&G9&"]"&E9&"'!"&$AA$3),0)} -> #VALUE! | P9: {=IF(AND(G9=INDIRECT("'["&G9&"]"&E9&"'!"&$AH$2),OR(VALUE(I9)=INDIRECT("'["&G9&"]"&E9&"'!"&$AB$2))),INDIRECT("'["&G9&"]"&E9&"'!"&$AB$3),0)} -> #VALUE! | Q9: {=IF(AND(G9=INDIRECT("'["&G9&"]"&E9&"'!"&$AH$2),OR(VALUE(I9)=INDIRECT("'["&G9&"]"&E9&"'!"&$AC$2))),INDIRECT("'["&G9&"]"&E9&"'!"&$AC$3),0)} -> #VALUE! | R9: {=IF(AND(G9=INDIRECT("'["&G9&"]"&E9&"'!"&$AH$2),OR(I9=INDIRECT("'["&G9&"]"&E9&"'!"&$AD$2))),INDIRECT("'["&G9&"]"&E9&"'!"&$AD$3),0)} -> #VALUE! | S9: {=IF(AND(G9=INDIRECT("'["&G9&"]"&E9&"'!"&$AH$2),OR(I9=INDIRECT("'["&G9&"]"&E9&"'!"&$AE$2))),INDIRECT("'["&G9&"]"&E9&"'!"&$AE$3),0)} -> #VALUE! | T9: {=IF(AND(G9=INDIRECT("'["&G9&"]"&E9&"'!"&$AH$2),OR(I9=INDIRECT("'["&G9&"]"&E9&"'!"&$AF$2))),INDIRECT("'["&G9&"]"&E9&"'!"&$AF$3),0)} -> #VALUE! | U9: {=IF(AND(G9=INDIRECT("'["&G9&"]"&E9&"'!"&$AH$2),OR(I9=INDIRECT("'["&G9&"]"&E9&"'!"&$AG$2))),INDIRECT("'["&G9&"]"&E9&"'!"&$AG$3),0)} -> #VALUE! | V9: =MID(B9,7,9) | W9: {=IF(AND(G9=INDIRECT("'["&G9&"]"&E9&"'!"&$AH$2),OR(V9=INDIRECT("'["&G9&"]"&E9&"'!"&$AI$2))),INDIRECT("'["&G9&"]"&E9&"'!"&$AI$3),0)} -> #VALUE! | AJ9: 1 | AK9: =(C9*AJ9%) -> 0 | AL9: =C9-AK9 -> 0 | AM9: =IF(A9<>"",IF(AM9="",NOW(),AM9),"") | AN9: =IF(VALUE(N9),"/","") -> #VALUE! | AO9: =IF(VALUE(O9),"/","") -> #VALUE! | AP9: =IF(ISTEXT(W9),"อายัด","") | AQ9: =IF(AND(C9<>0, C10=0), SUM($C$2:C9)-SUM($AQ$1:AQ8), "") | AR9: =IF(AND(AK9<>0, AK10=0), SUM($AK$2:AK9)-SUM($AR$1:AR8), "")
B10: =LEFT(A10,15) | C10: {=SUM(IF(ISNUMBER(M10:U10),M10:U10,""))} -> 0 | D10: =MID(A10,4,2) | E10: =IF(ISEVEN(D10),D10-1,VALUE(D10)) -> #VALUE! | F10: =LEFT(A10,2) | G10: =CONCATENATE(F10,".xlsx") -> .xlsx | H10: {=IF(AND(VALUE(E10)=INDIRECT("'["&G10&"]"&E10&"'!"&$X$2),G10=INDIRECT("'["&G10&"]"&E10&"'!"&$X$3)),INDIRECT("'["&G10&"]"&E10&"'!"&$X$1),0)} -> #VALUE! | I10: =MID(A10,10,6) | J10: =RIGHT(I10,2) | K10: =LEFT(I10,3) | L10: =RIGHT(I10,3) | M10: {=IF(AND(J10=INDIRECT("'["&G10&"]"&E10&"'!"&$Y$2),G10=INDIRECT("'["&G10&"]"&E10&"'!"&$AH$2)),INDIRECT("'["&G10&"]"&E10&"'!"&$Y$3),0)} -> #VALUE! | N10: {=IF(AND(G10=INDIRECT("'["&G10&"]"&E10&"'!"&$AH$2),OR(K10=INDIRECT("'["&G10&"]"&E10&"'!"&$Z$2))),INDIRECT("'["&G10&"]"&E10&"'!"&$Z$3),0)} -> #VALUE! | O10: {=IF(AND(G10=INDIRECT("'["&G10&"]"&E10&"'!"&$AH$2),OR(L10=INDIRECT("'["&G10&"]"&E10&"'!"&$AA$2))),INDIRECT("'["&G10&"]"&E10&"'!"&$AA$3),0)} -> #VALUE! | P10: {=IF(AND(G10=INDIRECT("'["&G10&"]"&E10&"'!"&$AH$2),OR(VALUE(I10)=INDIRECT("'["&G10&"]"&E10&"'!"&$AB$2))),INDIRECT("'["&G10&"]"&E10&"'!"&$AB$3),0)} -> #VALUE! | Q10: {=IF(AND(G10=INDIRECT("'["&G10&"]"&E10&"'!"&$AH$2),OR(VALUE(I10)=INDIRECT("'["&G10&"]"&E10&"'!"&$AC$2))),INDIRECT("'["&G10&"]"&E10&"'!"&$AC$3),0)} -> #VALUE! | R10: {=IF(AND(G10=INDIRECT("'["&G10&"]"&E10&"'!"&$AH$2),OR(I10=INDIRECT("'["&G10&"]"&E10&"'!"&$AD$2))),INDIRECT("'["&G10&"]"&E10&"'!"&$AD$3),0)} -> #VALUE! | S10: {=IF(AND(G10=INDIRECT("'["&G10&"]"&E10&"'!"&$AH$2),OR(I10=INDIRECT("'["&G10&"]"&E10&"'!"&$AE$2))),INDIRECT("'["&G10&"]"&E10&"'!"&$AE$3),0)} -> #VALUE! | T10: {=IF(AND(G10=INDIRECT("'["&G10&"]"&E10&"'!"&$AH$2),OR(I10=INDIRECT("'["&G10&"]"&E10&"'!"&$AF$2))),INDIRECT("'["&G10&"]"&E10&"'!"&$AF$3),0)} -> #VALUE! | U10: {=IF(AND(G10=INDIRECT("'["&G10&"]"&E10&"'!"&$AH$2),OR(I10=INDIRECT("'["&G10&"]"&E10&"'!"&$AG$2))),INDIRECT("'["&G10&"]"&E10&"'!"&$AG$3),0)} -> #VALUE! | V10: =MID(B10,7,9) | W10: {=IF(AND(G10=INDIRECT("'["&G10&"]"&E10&"'!"&$AH$2),OR(V10=INDIRECT("'["&G10&"]"&E10&"'!"&$AI$2))),INDIRECT("'["&G10&"]"&E10&"'!"&$AI$3),0)} -> #VALUE! | AJ10: 1 | AK10: =(C10*AJ10%) -> 0 | AL10: =C10-AK10 -> 0 | AM10: =IF(A10<>"",IF(AM10="",NOW(),AM10),"") | AN10: =IF(VALUE(N10),"/","") -> #VALUE! | AO10: =IF(VALUE(O10),"/","") -> #VALUE! | AP10: =IF(ISTEXT(W10),"อายัด","") | AQ10: =IF(AND(C10<>0, C11=0), SUM($C$2:C10)-SUM($AQ$1:AQ9), "") | AR10: =IF(AND(AK10<>0, AK11=0), SUM($AK$2:AK10)-SUM($AR$1:AR9), "")
B11: =LEFT(A11,15) | C11: {=SUM(IF(ISNUMBER(M11:U11),M11:U11,""))} -> 0 | D11: =MID(A11,4,2) | E11: =IF(ISEVEN(D11),D11-1,VALUE(D11)) -> #VALUE! | F11: =LEFT(A11,2) | G11: =CONCATENATE(F11,".xlsx") -> .xlsx | H11: {=IF(AND(VALUE(E11)=INDIRECT("'["&G11&"]"&E11&"'!"&$X$2),G11=INDIRECT("'["&G11&"]"&E11&"'!"&$X$3)),INDIRECT("'["&G11&"]"&E11&"'!"&$X$1),0)} -> #VALUE! | I11: =MID(A11,10,6) | J11: =RIGHT(I11,2) | K11: =LEFT(I11,3) | L11: =RIGHT(I11,3) | M11: {=IF(AND(J11=INDIRECT("'["&G11&"]"&E11&"'!"&$Y$2),G11=INDIRECT("'["&G11&"]"&E11&"'!"&$AH$2)),INDIRECT("'["&G11&"]"&E11&"'!"&$Y$3),0)} -> #VALUE! | N11: {=IF(AND(G11=INDIRECT("'["&G11&"]"&E11&"'!"&$AH$2),OR(K11=INDIRECT("'["&G11&"]"&E11&"'!"&$Z$2))),INDIRECT("'["&G11&"]"&E11&"'!"&$Z$3),0)} -> #VALUE! | O11: {=IF(AND(G11=INDIRECT("'["&G11&"]"&E11&"'!"&$AH$2),OR(L11=INDIRECT("'["&G11&"]"&E11&"'!"&$AA$2))),INDIRECT("'["&G11&"]"&E11&"'!"&$AA$3),0)} -> #VALUE! | P11: {=IF(AND(G11=INDIRECT("'["&G11&"]"&E11&"'!"&$AH$2),OR(VALUE(I11)=INDIRECT("'["&G11&"]"&E11&"'!"&$AB$2))),INDIRECT("'["&G11&"]"&E11&"'!"&$AB$3),0)} -> #VALUE! | Q11: {=IF(AND(G11=INDIRECT("'["&G11&"]"&E11&"'!"&$AH$2),OR(VALUE(I11)=INDIRECT("'["&G11&"]"&E11&"'!"&$AC$2))),INDIRECT("'["&G11&"]"&E11&"'!"&$AC$3),0)} -> #VALUE! | R11: {=IF(AND(G11=INDIRECT("'["&G11&"]"&E11&"'!"&$AH$2),OR(I11=INDIRECT("'["&G11&"]"&E11&"'!"&$AD$2))),INDIRECT("'["&G11&"]"&E11&"'!"&$AD$3),0)} -> #VALUE! | S11: {=IF(AND(G11=INDIRECT("'["&G11&"]"&E11&"'!"&$AH$2),OR(I11=INDIRECT("'["&G11&"]"&E11&"'!"&$AE$2))),INDIRECT("'["&G11&"]"&E11&"'!"&$AE$3),0)} -> #VALUE! | T11: {=IF(AND(G11=INDIRECT("'["&G11&"]"&E11&"'!"&$AH$2),OR(I11=INDIRECT("'["&G11&"]"&E11&"'!"&$AF$2))),INDIRECT("'["&G11&"]"&E11&"'!"&$AF$3),0)} -> #VALUE! | U11: {=IF(AND(G11=INDIRECT("'["&G11&"]"&E11&"'!"&$AH$2),OR(I11=INDIRECT("'["&G11&"]"&E11&"'!"&$AG$2))),INDIRECT("'["&G11&"]"&E11&"'!"&$AG$3),0)} -> #VALUE! | V11: =MID(B11,7,9) | W11: {=IF(AND(G11=INDIRECT("'["&G11&"]"&E11&"'!"&$AH$2),OR(V11=INDIRECT("'["&G11&"]"&E11&"'!"&$AI$2))),INDIRECT("'["&G11&"]"&E11&"'!"&$AI$3),0)} -> #VALUE! | AJ11: 1 | AK11: =(C11*AJ11%) -> 0 | AL11: =C11-AK11 -> 0 | AM11: =IF(A11<>"",IF(AM11="",NOW(),AM11),"") | AN11: =IF(VALUE(N11),"/","") -> #VALUE! | AO11: =IF(VALUE(O11),"/","") -> #VALUE! | AP11: =IF(ISTEXT(W11),"อายัด","") | AQ11: =IF(AND(C11<>0, C12=0), SUM($C$2:C11)-SUM($AQ$1:AQ10), "") | AR11: =IF(AND(AK11<>0, AK12=0), SUM($AK$2:AK11)-SUM($AR$1:AR10), "")
B12: =LEFT(A12,15) | C12: {=SUM(IF(ISNUMBER(M12:U12),M12:U12,""))} -> 0 | D12: =MID(A12,4,2) | E12: =IF(ISEVEN(D12),D12-1,VALUE(D12)) -> #VALUE! | F12: =LEFT(A12,2) | G12: =CONCATENATE(F12,".xlsx") -> .xlsx | H12: {=IF(AND(VALUE(E12)=INDIRECT("'["&G12&"]"&E12&"'!"&$X$2),G12=INDIRECT("'["&G12&"]"&E12&"'!"&$X$3)),INDIRECT("'["&G12&"]"&E12&"'!"&$X$1),0)} -> #VALUE! | I12: =MID(A12,10,6) | J12: =RIGHT(I12,2) | K12: =LEFT(I12,3) | L12: =RIGHT(I12,3) | M12: {=IF(AND(J12=INDIRECT("'["&G12&"]"&E12&"'!"&$Y$2),G12=INDIRECT("'["&G12&"]"&E12&"'!"&$AH$2)),INDIRECT("'["&G12&"]"&E12&"'!"&$Y$3),0)} -> #VALUE! | N12: {=IF(AND(G12=INDIRECT("'["&G12&"]"&E12&"'!"&$AH$2),OR(K12=INDIRECT("'["&G12&"]"&E12&"'!"&$Z$2))),INDIRECT("'["&G12&"]"&E12&"'!"&$Z$3),0)} -> #VALUE! | O12: {=IF(AND(G12=INDIRECT("'["&G12&"]"&E12&"'!"&$AH$2),OR(L12=INDIRECT("'["&G12&"]"&E12&"'!"&$AA$2))),INDIRECT("'["&G12&"]"&E12&"'!"&$AA$3),0)} -> #VALUE! | P12: {=IF(AND(G12=INDIRECT("'["&G12&"]"&E12&"'!"&$AH$2),OR(VALUE(I12)=INDIRECT("'["&G12&"]"&E12&"'!"&$AB$2))),INDIRECT("'["&G12&"]"&E12&"'!"&$AB$3),0)} -> #VALUE! | Q12: {=IF(AND(G12=INDIRECT("'["&G12&"]"&E12&"'!"&$AH$2),OR(VALUE(I12)=INDIRECT("'["&G12&"]"&E12&"'!"&$AC$2))),INDIRECT("'["&G12&"]"&E12&"'!"&$AC$3),0)} -> #VALUE! | R12: {=IF(AND(G12=INDIRECT("'["&G12&"]"&E12&"'!"&$AH$2),OR(I12=INDIRECT("'["&G12&"]"&E12&"'!"&$AD$2))),INDIRECT("'["&G12&"]"&E12&"'!"&$AD$3),0)} -> #VALUE! | S12: {=IF(AND(G12=INDIRECT("'["&G12&"]"&E12&"'!"&$AH$2),OR(I12=INDIRECT("'["&G12&"]"&E12&"'!"&$AE$2))),INDIRECT("'["&G12&"]"&E12&"'!"&$AE$3),0)} -> #VALUE! | T12: {=IF(AND(G12=INDIRECT("'["&G12&"]"&E12&"'!"&$AH$2),OR(I12=INDIRECT("'["&G12&"]"&E12&"'!"&$AF$2))),INDIRECT("'["&G12&"]"&E12&"'!"&$AF$3),0)} -> #VALUE! | U12: {=IF(AND(G12=INDIRECT("'["&G12&"]"&E12&"'!"&$AH$2),OR(I12=INDIRECT("'["&G12&"]"&E12&"'!"&$AG$2))),INDIRECT("'["&G12&"]"&E12&"'!"&$AG$3),0)} -> #VALUE! | V12: =MID(B12,7,9) | W12: {=IF(AND(G12=INDIRECT("'["&G12&"]"&E12&"'!"&$AH$2),OR(V12=INDIRECT("'["&G12&"]"&E12&"'!"&$AI$2))),INDIRECT("'["&G12&"]"&E12&"'!"&$AI$3),0)} -> #VALUE! | AJ12: 1 | AK12: =(C12*AJ12%) -> 0 | AL12: =C12-AK12 -> 0 | AM12: =IF(A12<>"",IF(AM12="",NOW(),AM12),"") | AN12: =IF(VALUE(N12),"/","") -> #VALUE! | AO12: =IF(VALUE(O12),"/","") -> #VALUE! | AP12: =IF(ISTEXT(W12),"อายัด","") | AQ12: =IF(AND(C12<>0, C13=0), SUM($C$2:C12)-SUM($AQ$1:AQ11), "") | AR12: =IF(AND(AK12<>0, AK13=0), SUM($AK$2:AK12)-SUM($AR$1:AR11), "")
B13: =LEFT(A13,15) | C13: {=SUM(IF(ISNUMBER(M13:U13),M13:U13,""))} -> 0 | D13: =MID(A13,4,2) | E13: =IF(ISEVEN(D13),D13-1,VALUE(D13)) -> #VALUE! | F13: =LEFT(A13,2) | G13: =CONCATENATE(F13,".xlsx") -> .xlsx | H13: {=IF(AND(VALUE(E13)=INDIRECT("'["&G13&"]"&E13&"'!"&$X$2),G13=INDIRECT("'["&G13&"]"&E13&"'!"&$X$3)),INDIRECT("'["&G13&"]"&E13&"'!"&$X$1),0)} -> #VALUE! | I13: =MID(A13,10,6) | J13: =RIGHT(I13,2) | K13: =LEFT(I13,3) | L13: =RIGHT(I13,3) | M13: {=IF(AND(J13=INDIRECT("'["&G13&"]"&E13&"'!"&$Y$2),G13=INDIRECT("'["&G13&"]"&E13&"'!"&$AH$2)),INDIRECT("'["&G13&"]"&E13&"'!"&$Y$3),0)} -> #VALUE! | N13: {=IF(AND(G13=INDIRECT("'["&G13&"]"&E13&"'!"&$AH$2),OR(K13=INDIRECT("'["&G13&"]"&E13&"'!"&$Z$2))),INDIRECT("'["&G13&"]"&E13&"'!"&$Z$3),0)} -> #VALUE! | O13: {=IF(AND(G13=INDIRECT("'["&G13&"]"&E13&"'!"&$AH$2),OR(L13=INDIRECT("'["&G13&"]"&E13&"'!"&$AA$2))),INDIRECT("'["&G13&"]"&E13&"'!"&$AA$3),0)} -> #VALUE! | P13: {=IF(AND(G13=INDIRECT("'["&G13&"]"&E13&"'!"&$AH$2),OR(VALUE(I13)=INDIRECT("'["&G13&"]"&E13&"'!"&$AB$2))),INDIRECT("'["&G13&"]"&E13&"'!"&$AB$3),0)} -> #VALUE! | Q13: {=IF(AND(G13=INDIRECT("'["&G13&"]"&E13&"'!"&$AH$2),OR(VALUE(I13)=INDIRECT("'["&G13&"]"&E13&"'!"&$AC$2))),INDIRECT("'["&G13&"]"&E13&"'!"&$AC$3),0)} -> #VALUE! | R13: {=IF(AND(G13=INDIRECT("'["&G13&"]"&E13&"'!"&$AH$2),OR(I13=INDIRECT("'["&G13&"]"&E13&"'!"&$AD$2))),INDIRECT("'["&G13&"]"&E13&"'!"&$AD$3),0)} -> #VALUE! | S13: {=IF(AND(G13=INDIRECT("'["&G13&"]"&E13&"'!"&$AH$2),OR(I13=INDIRECT("'["&G13&"]"&E13&"'!"&$AE$2))),INDIRECT("'["&G13&"]"&E13&"'!"&$AE$3),0)} -> #VALUE! | T13: {=IF(AND(G13=INDIRECT("'["&G13&"]"&E13&"'!"&$AH$2),OR(I13=INDIRECT("'["&G13&"]"&E13&"'!"&$AF$2))),INDIRECT("'["&G13&"]"&E13&"'!"&$AF$3),0)} -> #VALUE! | U13: {=IF(AND(G13=INDIRECT("'["&G13&"]"&E13&"'!"&$AH$2),OR(I13=INDIRECT("'["&G13&"]"&E13&"'!"&$AG$2))),INDIRECT("'["&G13&"]"&E13&"'!"&$AG$3),0)} -> #VALUE! | V13: =MID(B13,7,9) | W13: {=IF(AND(G13=INDIRECT("'["&G13&"]"&E13&"'!"&$AH$2),OR(V13=INDIRECT("'["&G13&"]"&E13&"'!"&$AI$2))),INDIRECT("'["&G13&"]"&E13&"'!"&$AI$3),0)} -> #VALUE! | AJ13: 1 | AK13: =(C13*AJ13%) -> 0 | AL13: =C13-AK13 -> 0 | AM13: =IF(A13<>"",IF(AM13="",NOW(),AM13),"") | AN13: =IF(VALUE(N13),"/","") -> #VALUE! | AO13: =IF(VALUE(O13),"/","") -> #VALUE! | AP13: =IF(ISTEXT(W13),"อายัด","") | AQ13: =IF(AND(C13<>0, C14=0), SUM($C$2:C13)-SUM($AQ$1:AQ12), "") | AR13: =IF(AND(AK13<>0, AK14=0), SUM($AK$2:AK13)-SUM($AR$1:AR12), "")
B14: =LEFT(A14,15) | C14: {=SUM(IF(ISNUMBER(M14:U14),M14:U14,""))} -> 0 | D14: =MID(A14,4,2) | E14: =IF(ISEVEN(D14),D14-1,VALUE(D14)) -> #VALUE! | F14: =LEFT(A14,2) | G14: =CONCATENATE(F14,".xlsx") -> .xlsx | H14: {=IF(AND(VALUE(E14)=INDIRECT("'["&G14&"]"&E14&"'!"&$X$2),G14=INDIRECT("'["&G14&"]"&E14&"'!"&$X$3)),INDIRECT("'["&G14&"]"&E14&"'!"&$X$1),0)} -> #VALUE! | I14: =MID(A14,10,6) | J14: =RIGHT(I14,2) | K14: =LEFT(I14,3) | L14: =RIGHT(I14,3) | M14: {=IF(AND(J14=INDIRECT("'["&G14&"]"&E14&"'!"&$Y$2),G14=INDIRECT("'["&G14&"]"&E14&"'!"&$AH$2)),INDIRECT("'["&G14&"]"&E14&"'!"&$Y$3),0)} -> #VALUE! | N14: {=IF(AND(G14=INDIRECT("'["&G14&"]"&E14&"'!"&$AH$2),OR(K14=INDIRECT("'["&G14&"]"&E14&"'!"&$Z$2))),INDIRECT("'["&G14&"]"&E14&"'!"&$Z$3),0)} -> #VALUE! | O14: {=IF(AND(G14=INDIRECT("'["&G14&"]"&E14&"'!"&$AH$2),OR(L14=INDIRECT("'["&G14&"]"&E14&"'!"&$AA$2))),INDIRECT("'["&G14&"]"&E14&"'!"&$AA$3),0)} -> #VALUE! | P14: {=IF(AND(G14=INDIRECT("'["&G14&"]"&E14&"'!"&$AH$2),OR(VALUE(I14)=INDIRECT("'["&G14&"]"&E14&"'!"&$AB$2))),INDIRECT("'["&G14&"]"&E14&"'!"&$AB$3),0)} -> #VALUE! | Q14: {=IF(AND(G14=INDIRECT("'["&G14&"]"&E14&"'!"&$AH$2),OR(VALUE(I14)=INDIRECT("'["&G14&"]"&E14&"'!"&$AC$2))),INDIRECT("'["&G14&"]"&E14&"'!"&$AC$3),0)} -> #VALUE! | R14: {=IF(AND(G14=INDIRECT("'["&G14&"]"&E14&"'!"&$AH$2),OR(I14=INDIRECT("'["&G14&"]"&E14&"'!"&$AD$2))),INDIRECT("'["&G14&"]"&E14&"'!"&$AD$3),0)} -> #VALUE! | S14: {=IF(AND(G14=INDIRECT("'["&G14&"]"&E14&"'!"&$AH$2),OR(I14=INDIRECT("'["&G14&"]"&E14&"'!"&$AE$2))),INDIRECT("'["&G14&"]"&E14&"'!"&$AE$3),0)} -> #VALUE! | T14: {=IF(AND(G14=INDIRECT("'["&G14&"]"&E14&"'!"&$AH$2),OR(I14=INDIRECT("'["&G14&"]"&E14&"'!"&$AF$2))),INDIRECT("'["&G14&"]"&E14&"'!"&$AF$3),0)} -> #VALUE! | U14: {=IF(AND(G14=INDIRECT("'["&G14&"]"&E14&"'!"&$AH$2),OR(I14=INDIRECT("'["&G14&"]"&E14&"'!"&$AG$2))),INDIRECT("'["&G14&"]"&E14&"'!"&$AG$3),0)} -> #VALUE! | V14: =MID(B14,7,9) | W14: {=IF(AND(G14=INDIRECT("'["&G14&"]"&E14&"'!"&$AH$2),OR(V14=INDIRECT("'["&G14&"]"&E14&"'!"&$AI$2))),INDIRECT("'["&G14&"]"&E14&"'!"&$AI$3),0)} -> #VALUE! | AJ14: 1 | AK14: =(C14*AJ14%) -> 0 | AL14: =C14-AK14 -> 0 | AM14: =IF(A14<>"",IF(AM14="",NOW(),AM14),"") | AN14: =IF(VALUE(N14),"/","") -> #VALUE! | AO14: =IF(VALUE(O14),"/","") -> #VALUE! | AP14: =IF(ISTEXT(W14),"อายัด","") | AQ14: =IF(AND(C14<>0, C15=0), SUM($C$2:C14)-SUM($AQ$1:AQ13), "") | AR14: =IF(AND(AK14<>0, AK15=0), SUM($AK$2:AK14)-SUM($AR$1:AR13), "")
B15: =LEFT(A15,15) | C15: {=SUM(IF(ISNUMBER(M15:U15),M15:U15,""))} -> 0 | D15: =MID(A15,4,2) | E15: =IF(ISEVEN(D15),D15-1,VALUE(D15)) -> #VALUE! | F15: =LEFT(A15,2) | G15: =CONCATENATE(F15,".xlsx") -> .xlsx | H15: {=IF(AND(VALUE(E15)=INDIRECT("'["&G15&"]"&E15&"'!"&$X$2),G15=INDIRECT("'["&G15&"]"&E15&"'!"&$X$3)),INDIRECT("'["&G15&"]"&E15&"'!"&$X$1),0)} -> #VALUE! | I15: =MID(A15,10,6) | J15: =RIGHT(I15,2) | K15: =LEFT(I15,3) | L15: =RIGHT(I15,3) | M15: {=IF(AND(J15=INDIRECT("'["&G15&"]"&E15&"'!"&$Y$2),G15=INDIRECT("'["&G15&"]"&E15&"'!"&$AH$2)),INDIRECT("'["&G15&"]"&E15&"'!"&$Y$3),0)} -> #VALUE! | N15: {=IF(AND(G15=INDIRECT("'["&G15&"]"&E15&"'!"&$AH$2),OR(K15=INDIRECT("'["&G15&"]"&E15&"'!"&$Z$2))),INDIRECT("'["&G15&"]"&E15&"'!"&$Z$3),0)} -> #VALUE! | O15: {=IF(AND(G15=INDIRECT("'["&G15&"]"&E15&"'!"&$AH$2),OR(L15=INDIRECT("'["&G15&"]"&E15&"'!"&$AA$2))),INDIRECT("'["&G15&"]"&E15&"'!"&$AA$3),0)} -> #VALUE! | P15: {=IF(AND(G15=INDIRECT("'["&G15&"]"&E15&"'!"&$AH$2),OR(VALUE(I15)=INDIRECT("'["&G15&"]"&E15&"'!"&$AB$2))),INDIRECT("'["&G15&"]"&E15&"'!"&$AB$3),0)} -> #VALUE! | Q15: {=IF(AND(G15=INDIRECT("'["&G15&"]"&E15&"'!"&$AH$2),OR(VALUE(I15)=INDIRECT("'["&G15&"]"&E15&"'!"&$AC$2))),INDIRECT("'["&G15&"]"&E15&"'!"&$AC$3),0)} -> #VALUE! | R15: {=IF(AND(G15=INDIRECT("'["&G15&"]"&E15&"'!"&$AH$2),OR(I15=INDIRECT("'["&G15&"]"&E15&"'!"&$AD$2))),INDIRECT("'["&G15&"]"&E15&"'!"&$AD$3),0)} -> #VALUE! | S15: {=IF(AND(G15=INDIRECT("'["&G15&"]"&E15&"'!"&$AH$2),OR(I15=INDIRECT("'["&G15&"]"&E15&"'!"&$AE$2))),INDIRECT("'["&G15&"]"&E15&"'!"&$AE$3),0)} -> #VALUE! | T15: {=IF(AND(G15=INDIRECT("'["&G15&"]"&E15&"'!"&$AH$2),OR(I15=INDIRECT("'["&G15&"]"&E15&"'!"&$AF$2))),INDIRECT("'["&G15&"]"&E15&"'!"&$AF$3),0)} -> #VALUE! | U15: {=IF(AND(G15=INDIRECT("'["&G15&"]"&E15&"'!"&$AH$2),OR(I15=INDIRECT("'["&G15&"]"&E15&"'!"&$AG$2))),INDIRECT("'["&G15&"]"&E15&"'!"&$AG$3),0)} -> #VALUE! | V15: =MID(B15,7,9) | W15: {=IF(AND(G15=INDIRECT("'["&G15&"]"&E15&"'!"&$AH$2),OR(V15=INDIRECT("'["&G15&"]"&E15&"'!"&$AI$2))),INDIRECT("'["&G15&"]"&E15&"'!"&$AI$3),0)} -> #VALUE! | AJ15: 1 | AK15: =(C15*AJ15%) -> 0 | AL15: =C15-AK15 -> 0 | AM15: =IF(A15<>"",IF(AM15="",NOW(),AM15),"") | AN15: =IF(VALUE(N15),"/","") -> #VALUE! | AO15: =IF(VALUE(O15),"/","") -> #VALUE! | AP15: =IF(ISTEXT(W15),"อายัด","") | AQ15: =IF(AND(C15<>0, C16=0), SUM($C$2:C15)-SUM($AQ$1:AQ14), "") | AR15: =IF(AND(AK15<>0, AK16=0), SUM($AK$2:AK15)-SUM($AR$1:AR14), "")
B16: =LEFT(A16,15) | C16: {=SUM(IF(ISNUMBER(M16:U16),M16:U16,""))} -> 0 | D16: =MID(A16,4,2) | E16: =IF(ISEVEN(D16),D16-1,VALUE(D16)) -> #VALUE! | F16: =LEFT(A16,2) | G16: =CONCATENATE(F16,".xlsx") -> .xlsx | H16: {=IF(AND(VALUE(E16)=INDIRECT("'["&G16&"]"&E16&"'!"&$X$2),G16=INDIRECT("'["&G16&"]"&E16&"'!"&$X$3)),INDIRECT("'["&G16&"]"&E16&"'!"&$X$1),0)} -> #VALUE! | I16: =MID(A16,10,6) | J16: =RIGHT(I16,2) | K16: =LEFT(I16,3) | L16: =RIGHT(I16,3) | M16: {=IF(AND(J16=INDIRECT("'["&G16&"]"&E16&"'!"&$Y$2),G16=INDIRECT("'["&G16&"]"&E16&"'!"&$AH$2)),INDIRECT("'["&G16&"]"&E16&"'!"&$Y$3),0)} -> #VALUE! | N16: {=IF(AND(G16=INDIRECT("'["&G16&"]"&E16&"'!"&$AH$2),OR(K16=INDIRECT("'["&G16&"]"&E16&"'!"&$Z$2))),INDIRECT("'["&G16&"]"&E16&"'!"&$Z$3),0)} -> #VALUE! | O16: {=IF(AND(G16=INDIRECT("'["&G16&"]"&E16&"'!"&$AH$2),OR(L16=INDIRECT("'["&G16&"]"&E16&"'!"&$AA$2))),INDIRECT("'["&G16&"]"&E16&"'!"&$AA$3),0)} -> #VALUE! | P16: {=IF(AND(G16=INDIRECT("'["&G16&"]"&E16&"'!"&$AH$2),OR(VALUE(I16)=INDIRECT("'["&G16&"]"&E16&"'!"&$AB$2))),INDIRECT("'["&G16&"]"&E16&"'!"&$AB$3),0)} -> #VALUE! | Q16: {=IF(AND(G16=INDIRECT("'["&G16&"]"&E16&"'!"&$AH$2),OR(VALUE(I16)=INDIRECT("'["&G16&"]"&E16&"'!"&$AC$2))),INDIRECT("'["&G16&"]"&E16&"'!"&$AC$3),0)} -> #VALUE! | R16: {=IF(AND(G16=INDIRECT("'["&G16&"]"&E16&"'!"&$AH$2),OR(I16=INDIRECT("'["&G16&"]"&E16&"'!"&$AD$2))),INDIRECT("'["&G16&"]"&E16&"'!"&$AD$3),0)} -> #VALUE! | S16: {=IF(AND(G16=INDIRECT("'["&G16&"]"&E16&"'!"&$AH$2),OR(I16=INDIRECT("'["&G16&"]"&E16&"'!"&$AE$2))),INDIRECT("'["&G16&"]"&E16&"'!"&$AE$3),0)} -> #VALUE! | T16: {=IF(AND(G16=INDIRECT("'["&G16&"]"&E16&"'!"&$AH$2),OR(I16=INDIRECT("'["&G16&"]"&E16&"'!"&$AF$2))),INDIRECT("'["&G16&"]"&E16&"'!"&$AF$3),0)} -> #VALUE! | U16: {=IF(AND(G16=INDIRECT("'["&G16&"]"&E16&"'!"&$AH$2),OR(I16=INDIRECT("'["&G16&"]"&E16&"'!"&$AG$2))),INDIRECT("'["&G16&"]"&E16&"'!"&$AG$3),0)} -> #VALUE! | V16: =MID(B16,7,9) | W16: {=IF(AND(G16=INDIRECT("'["&G16&"]"&E16&"'!"&$AH$2),OR(V16=INDIRECT("'["&G16&"]"&E16&"'!"&$AI$2))),INDIRECT("'["&G16&"]"&E16&"'!"&$AI$3),0)} -> #VALUE! | AJ16: 1 | AK16: =(C16*AJ16%) -> 0 | AL16: =C16-AK16 -> 0 | AM16: =IF(A16<>"",IF(AM16="",NOW(),AM16),"") | AN16: =IF(VALUE(N16),"/","") -> #VALUE! | AO16: =IF(VALUE(O16),"/","") -> #VALUE! | AP16: =IF(ISTEXT(W16),"อายัด","") | AQ16: =IF(AND(C16<>0, C17=0), SUM($C$2:C16)-SUM($AQ$1:AQ15), "") | AR16: =IF(AND(AK16<>0, AK17=0), SUM($AK$2:AK16)-SUM($AR$1:AR15), "")
B17: =LEFT(A17,15) | C17: {=SUM(IF(ISNUMBER(M17:U17),M17:U17,""))} -> 0 | D17: =MID(A17,4,2) | E17: =IF(ISEVEN(D17),D17-1,VALUE(D17)) -> #VALUE! | F17: =LEFT(A17,2) | G17: =CONCATENATE(F17,".xlsx") -> .xlsx | H17: {=IF(AND(VALUE(E17)=INDIRECT("'["&G17&"]"&E17&"'!"&$X$2),G17=INDIRECT("'["&G17&"]"&E17&"'!"&$X$3)),INDIRECT("'["&G17&"]"&E17&"'!"&$X$1),0)} -> #VALUE! | I17: =MID(A17,10,6) | J17: =RIGHT(I17,2) | K17: =LEFT(I17,3) | L17: =RIGHT(I17,3) | M17: {=IF(AND(J17=INDIRECT("'["&G17&"]"&E17&"'!"&$Y$2),G17=INDIRECT("'["&G17&"]"&E17&"'!"&$AH$2)),INDIRECT("'["&G17&"]"&E17&"'!"&$Y$3),0)} -> #VALUE! | N17: {=IF(AND(G17=INDIRECT("'["&G17&"]"&E17&"'!"&$AH$2),OR(K17=INDIRECT("'["&G17&"]"&E17&"'!"&$Z$2))),INDIRECT("'["&G17&"]"&E17&"'!"&$Z$3),0)} -> #VALUE! | O17: {=IF(AND(G17=INDIRECT("'["&G17&"]"&E17&"'!"&$AH$2),OR(L17=INDIRECT("'["&G17&"]"&E17&"'!"&$AA$2))),INDIRECT("'["&G17&"]"&E17&"'!"&$AA$3),0)} -> #VALUE! | P17: {=IF(AND(G17=INDIRECT("'["&G17&"]"&E17&"'!"&$AH$2),OR(VALUE(I17)=INDIRECT("'["&G17&"]"&E17&"'!"&$AB$2))),INDIRECT("'["&G17&"]"&E17&"'!"&$AB$3),0)} -> #VALUE! | Q17: {=IF(AND(G17=INDIRECT("'["&G17&"]"&E17&"'!"&$AH$2),OR(VALUE(I17)=INDIRECT("'["&G17&"]"&E17&"'!"&$AC$2))),INDIRECT("'["&G17&"]"&E17&"'!"&$AC$3),0)} -> #VALUE! | R17: {=IF(AND(G17=INDIRECT("'["&G17&"]"&E17&"'!"&$AH$2),OR(I17=INDIRECT("'["&G17&"]"&E17&"'!"&$AD$2))),INDIRECT("'["&G17&"]"&E17&"'!"&$AD$3),0)} -> #VALUE! | S17: {=IF(AND(G17=INDIRECT("'["&G17&"]"&E17&"'!"&$AH$2),OR(I17=INDIRECT("'["&G17&"]"&E17&"'!"&$AE$2))),INDIRECT("'["&G17&"]"&E17&"'!"&$AE$3),0)} -> #VALUE! | T17: {=IF(AND(G17=INDIRECT("'["&G17&"]"&E17&"'!"&$AH$2),OR(I17=INDIRECT("'["&G17&"]"&E17&"'!"&$AF$2))),INDIRECT("'["&G17&"]"&E17&"'!"&$AF$3),0)} -> #VALUE! | U17: {=IF(AND(G17=INDIRECT("'["&G17&"]"&E17&"'!"&$AH$2),OR(I17=INDIRECT("'["&G17&"]"&E17&"'!"&$AG$2))),INDIRECT("'["&G17&"]"&E17&"'!"&$AG$3),0)} -> #VALUE! | V17: =MID(B17,7,9) | W17: {=IF(AND(G17=INDIRECT("'["&G17&"]"&E17&"'!"&$AH$2),OR(V17=INDIRECT("'["&G17&"]"&E17&"'!"&$AI$2))),INDIRECT("'["&G17&"]"&E17&"'!"&$AI$3),0)} -> #VALUE! | AJ17: 1 | AK17: =(C17*AJ17%) -> 0 | AL17: =C17-AK17 -> 0 | AM17: =IF(A17<>"",IF(AM17="",NOW(),AM17),"") | AN17: =IF(VALUE(N17),"/","") -> #VALUE! | AO17: =IF(VALUE(O17),"/","") -> #VALUE! | AP17: =IF(ISTEXT(W17),"อายัด","") | AQ17: =IF(AND(C17<>0, C18=0), SUM($C$2:C17)-SUM($AQ$1:AQ16), "") | AR17: =IF(AND(AK17<>0, AK18=0), SUM($AK$2:AK17)-SUM($AR$1:AR16), "")
... B319: =LEFT(A319,15) | C319: {=SUM(IF(ISNUMBER(M319:U319),M319:U319,""))} -> 0 | D319: =MID(A319,4,2) | E319: =IF(ISEVEN(D319),D319-1,VALUE(D319)) -> #VALUE! | F319: =LEFT(A319,2) | G319: =CONCATENATE(F319,".xlsx") -> .xlsx | H319: {=IF(AND(VALUE(E319)=INDIRECT("'["&G319&"]"&E319&"'!"&$X$2),G319=INDIRECT("'["&G319&"]"&E319&"'!"&$X$3)),INDIRECT("'["&G319&"]"&E319&"'!"&$X$1),0)} -> #VALUE! | I319: =MID(A319,10,6) | J319: =RIGHT(I319,2) | K319: =LEFT(I319,3) | L319: =RIGHT(I319,3) | M319: {=IF(AND(J319=INDIRECT("'["&G319&"]"&E319&"'!"&$Y$2),G319=INDIRECT("'["&G319&"]"&E319&"'!"&$AH$2)),INDIRECT("'["&G319&"]"&E319&"'!"&$Y$3),0)} -> #VALUE! | N319: {=IF(AND(G319=INDIRECT("'["&G319&"]"&E319&"'!"&$AH$2),OR(K319=INDIRECT("'["&G319&"]"&E319&"'!"&$Z$2))),INDIRECT("'["&G319&"]"&E319&"'!"&$Z$3),0)} -> #VALUE! | O319: {=IF(AND(G319=INDIRECT("'["&G319&"]"&E319&"'!"&$AH$2),OR(L319=INDIRECT("'["&G319&"]"&E319&"'!"&$AA$2))),INDIRECT("'["&G319&"]"&E319&"'!"&$AA$3),0)} -> #VALUE! | P319: {=IF(AND(G319=INDIRECT("'["&G319&"]"&E319&"'!"&$AH$2),OR(VALUE(I319)=INDIRECT("'["&G319&"]"&E319&"'!"&$AB$2))),INDIRECT("'["&G319&"]"&E319&"'!"&$AB$3),0)} -> #VALUE! | Q319: {=IF(AND(G319=INDIRECT("'["&G319&"]"&E319&"'!"&$AH$2),OR(VALUE(I319)=INDIRECT("'["&G319&"]"&E319&"'!"&$AC$2))),INDIRECT("'["&G319&"]"&E319&"'!"&$AC$3),0)} -> #VALUE! | R319: {=IF(AND(G319=INDIRECT("'["&G319&"]"&E319&"'!"&$AH$2),OR(I319=INDIRECT("'["&G319&"]"&E319&"'!"&$AD$2))),INDIRECT("'["&G319&"]"&E319&"'!"&$AD$3),0)} -> #VALUE! | S319: {=IF(AND(G319=INDIRECT("'["&G319&"]"&E319&"'!"&$AH$2),OR(I319=INDIRECT("'["&G319&"]"&E319&"'!"&$AE$2))),INDIRECT("'["&G319&"]"&E319&"'!"&$AE$3),0)} -> #VALUE! | T319: {=IF(AND(G319=INDIRECT("'["&G319&"]"&E319&"'!"&$AH$2),OR(I319=INDIRECT("'["&G319&"]"&E319&"'!"&$AF$2))),INDIRECT("'["&G319&"]"&E319&"'!"&$AF$3),0)} -> #VALUE! | U319: {=IF(AND(G319=INDIRECT("'["&G319&"]"&E319&"'!"&$AH$2),OR(I319=INDIRECT("'["&G319&"]"&E319&"'!"&$AG$2))),INDIRECT("'["&G319&"]"&E319&"'!"&$AG$3),0)} -> #VALUE! | V319: =MID(B319,7,9) | W319: {=IF(AND(G319=INDIRECT("'["&G319&"]"&E319&"'!"&$AH$2),OR(V319=INDIRECT("'["&G319&"]"&E319&"'!"&$AI$2))),INDIRECT("'["&G319&"]"&E319&"'!"&$AI$3),0)} -> #VALUE! | AJ319: 1 | AK319: =(C319*AJ319%) -> 0 | AL319: =C319-AK319 -> 0 | AM319: =IF(A319<>"",IF(AM319="",NOW(),AM319),"") | AN319: =IF(VALUE(N319),"/","") -> #VALUE! | AO319: =IF(VALUE(O319),"/","") -> #VALUE! | AP319: =IF(ISTEXT(W319),"อายัด","") | AQ319: =IF(AND(C319<>0, C320=0), SUM($C$2:C319)-SUM($AQ$1:AQ318), "") | AR319: =IF(AND(AK319<>0, AK320=0), SUM($AK$2:AK319)-SUM($AR$1:AR318), "")
B320: =LEFT(A320,15) | C320: {=SUM(IF(ISNUMBER(M320:U320),M320:U320,""))} -> 0 | D320: =MID(A320,4,2) | E320: =IF(ISEVEN(D320),D320-1,VALUE(D320)) -> #VALUE! | F320: =LEFT(A320,2) | G320: =CONCATENATE(F320,".xlsx") -> .xlsx | H320: {=IF(AND(VALUE(E320)=INDIRECT("'["&G320&"]"&E320&"'!"&$X$2),G320=INDIRECT("'["&G320&"]"&E320&"'!"&$X$3)),INDIRECT("'["&G320&"]"&E320&"'!"&$X$1),0)} -> #VALUE! | I320: =MID(A320,10,6) | J320: =RIGHT(I320,2) | K320: =LEFT(I320,3) | L320: =RIGHT(I320,3) | M320: {=IF(AND(J320=INDIRECT("'["&G320&"]"&E320&"'!"&$Y$2),G320=INDIRECT("'["&G320&"]"&E320&"'!"&$AH$2)),INDIRECT("'["&G320&"]"&E320&"'!"&$Y$3),0)} -> #VALUE! | N320: {=IF(AND(G320=INDIRECT("'["&G320&"]"&E320&"'!"&$AH$2),OR(K320=INDIRECT("'["&G320&"]"&E320&"'!"&$Z$2))),INDIRECT("'["&G320&"]"&E320&"'!"&$Z$3),0)} -> #VALUE! | O320: {=IF(AND(G320=INDIRECT("'["&G320&"]"&E320&"'!"&$AH$2),OR(L320=INDIRECT("'["&G320&"]"&E320&"'!"&$AA$2))),INDIRECT("'["&G320&"]"&E320&"'!"&$AA$3),0)} -> #VALUE! | P320: {=IF(AND(G320=INDIRECT("'["&G320&"]"&E320&"'!"&$AH$2),OR(VALUE(I320)=INDIRECT("'["&G320&"]"&E320&"'!"&$AB$2))),INDIRECT("'["&G320&"]"&E320&"'!"&$AB$3),0)} -> #VALUE! | Q320: {=IF(AND(G320=INDIRECT("'["&G320&"]"&E320&"'!"&$AH$2),OR(VALUE(I320)=INDIRECT("'["&G320&"]"&E320&"'!"&$AC$2))),INDIRECT("'["&G320&"]"&E320&"'!"&$AC$3),0)} -> #VALUE! | R320: {=IF(AND(G320=INDIRECT("'["&G320&"]"&E320&"'!"&$AH$2),OR(I320=INDIRECT("'["&G320&"]"&E320&"'!"&$AD$2))),INDIRECT("'["&G320&"]"&E320&"'!"&$AD$3),0)} -> #VALUE! | S320: {=IF(AND(G320=INDIRECT("'["&G320&"]"&E320&"'!"&$AH$2),OR(I320=INDIRECT("'["&G320&"]"&E320&"'!"&$AE$2))),INDIRECT("'["&G320&"]"&E320&"'!"&$AE$3),0)} -> #VALUE! | T320: {=IF(AND(G320=INDIRECT("'["&G320&"]"&E320&"'!"&$AH$2),OR(I320=INDIRECT("'["&G320&"]"&E320&"'!"&$AF$2))),INDIRECT("'["&G320&"]"&E320&"'!"&$AF$3),0)} -> #VALUE! | U320: {=IF(AND(G320=INDIRECT("'["&G320&"]"&E320&"'!"&$AH$2),OR(I320=INDIRECT("'["&G320&"]"&E320&"'!"&$AG$2))),INDIRECT("'["&G320&"]"&E320&"'!"&$AG$3),0)} -> #VALUE! | V320: =MID(B320,7,9) | W320: {=IF(AND(G320=INDIRECT("'["&G320&"]"&E320&"'!"&$AH$2),OR(V320=INDIRECT("'["&G320&"]"&E320&"'!"&$AI$2))),INDIRECT("'["&G320&"]"&E320&"'!"&$AI$3),0)} -> #VALUE! | X320: รวม | AJ320: 1 | AK320: =(C320*AJ320%) -> 0 | AL320: =C320-AK320 -> 0 | AM320: =IF(A320<>"",IF(AM320="",NOW(),AM320),"") | AN320: =IF(VALUE(N320),"/","") -> #VALUE! | AO320: =IF(VALUE(O320),"/","") -> #VALUE! | AP320: =IF(ISTEXT(W320),"อายัด","") | AQ320: =IF(AND(C320<>0, C321=0), SUM($C$2:C320)-SUM($AQ$1:AQ319), "") | AR320: =IF(AND(AK320<>0, AK321=0), SUM($AK$2:AK320)-SUM($AR$1:AR319), "")
B321: =LEFT(A321,15) | C321: {=SUM(IF(ISNUMBER(M321:U321),M321:U321,""))} -> 0 | D321: =MID(A321,4,2) | E321: =IF(ISEVEN(D321),D321-1,VALUE(D321)) -> #VALUE! | F321: =LEFT(A321,2) | G321: =CONCATENATE(F321,".xlsx") -> .xlsx | H321: {=IF(AND(VALUE(E321)=INDIRECT("'["&G321&"]"&E321&"'!"&$X$2),G321=INDIRECT("'["&G321&"]"&E321&"'!"&$X$3)),INDIRECT("'["&G321&"]"&E321&"'!"&$X$1),0)} -> #VALUE! | I321: =MID(A321,10,6) | J321: =RIGHT(I321,2) | K321: =LEFT(I321,3) | L321: =RIGHT(I321,3) | M321: {=IF(AND(J321=INDIRECT("'["&G321&"]"&E321&"'!"&$Y$2),G321=INDIRECT("'["&G321&"]"&E321&"'!"&$AH$2)),INDIRECT("'["&G321&"]"&E321&"'!"&$Y$3),0)} -> #VALUE! | N321: {=IF(AND(G321=INDIRECT("'["&G321&"]"&E321&"'!"&$AH$2),OR(K321=INDIRECT("'["&G321&"]"&E321&"'!"&$Z$2))),INDIRECT("'["&G321&"]"&E321&"'!"&$Z$3),0)} -> #VALUE! | O321: {=IF(AND(G321=INDIRECT("'["&G321&"]"&E321&"'!"&$AH$2),OR(L321=INDIRECT("'["&G321&"]"&E321&"'!"&$AA$2))),INDIRECT("'["&G321&"]"&E321&"'!"&$AA$3),0)} -> #VALUE! | P321: {=IF(AND(G321=INDIRECT("'["&G321&"]"&E321&"'!"&$AH$2),OR(VALUE(I321)=INDIRECT("'["&G321&"]"&E321&"'!"&$AB$2))),INDIRECT("'["&G321&"]"&E321&"'!"&$AB$3),0)} -> #VALUE! | Q321: {=IF(AND(G321=INDIRECT("'["&G321&"]"&E321&"'!"&$AH$2),OR(VALUE(I321)=INDIRECT("'["&G321&"]"&E321&"'!"&$AC$2))),INDIRECT("'["&G321&"]"&E321&"'!"&$AC$3),0)} -> #VALUE! | R321: {=IF(AND(G321=INDIRECT("'["&G321&"]"&E321&"'!"&$AH$2),OR(I321=INDIRECT("'["&G321&"]"&E321&"'!"&$AD$2))),INDIRECT("'["&G321&"]"&E321&"'!"&$AD$3),0)} -> #VALUE! | S321: {=IF(AND(G321=INDIRECT("'["&G321&"]"&E321&"'!"&$AH$2),OR(I321=INDIRECT("'["&G321&"]"&E321&"'!"&$AE$2))),INDIRECT("'["&G321&"]"&E321&"'!"&$AE$3),0)} -> #VALUE! | T321: {=IF(AND(G321=INDIRECT("'["&G321&"]"&E321&"'!"&$AH$2),OR(I321=INDIRECT("'["&G321&"]"&E321&"'!"&$AF$2))),INDIRECT("'["&G321&"]"&E321&"'!"&$AF$3),0)} -> #VALUE! | U321: {=IF(AND(G321=INDIRECT("'["&G321&"]"&E321&"'!"&$AH$2),OR(I321=INDIRECT("'["&G321&"]"&E321&"'!"&$AG$2))),INDIRECT("'["&G321&"]"&E321&"'!"&$AG$3),0)} -> #VALUE! | V321: =MID(B321,7,9) | W321: {=IF(AND(G321=INDIRECT("'["&G321&"]"&E321&"'!"&$AH$2),OR(V321=INDIRECT("'["&G321&"]"&E321&"'!"&$AI$2))),INDIRECT("'["&G321&"]"&E321&"'!"&$AI$3),0)} -> #VALUE! | X321: {=SUM(IF(ISNUMBER(C162:C321),C162:C321,""))} -> 0 | AJ321: 1 | AK321: =(C321*AJ321%) -> 0 | AL321: =C321-AK321 -> 0 | AM321: =IF(A321<>"",IF(AM321="",NOW(),AM321),"") | AN321: =IF(VALUE(N321),"/","") -> #VALUE! | AO321: =IF(VALUE(O321),"/","") -> #VALUE! | AP321: =IF(ISTEXT(W321),"อายัด","") | AQ321: =IF(AND(C321<>0, C322=0), SUM($C$2:C321)-SUM($AQ$1:AQ320), "") | AR321: =IF(AND(AK321<>0, AK322=0), SUM($AK$2:AK321)-SUM($AR$1:AR320), "")
B322: =LEFT(A322,15) | C322: {=SUM(IF(ISNUMBER(M322:U322),M322:U322,""))} -> 0 | D322: =MID(A322,4,2) | E322: =IF(ISEVEN(D322),D322-1,VALUE(D322)) -> #VALUE! | F322: =LEFT(A322,2) | G322: =CONCATENATE(F322,".xlsx") -> .xlsx | H322: {=IF(AND(VALUE(E322)=INDIRECT("'["&G322&"]"&E322&"'!"&$X$2),G322=INDIRECT("'["&G322&"]"&E322&"'!"&$X$3)),INDIRECT("'["&G322&"]"&E322&"'!"&$X$1),0)} -> #VALUE! | I322: =MID(A322,10,6) | J322: =RIGHT(I322,2) | K322: =LEFT(I322,3) | L322: =RIGHT(I322,3) | M322: {=IF(AND(J322=INDIRECT("'["&G322&"]"&E322&"'!"&$Y$2),G322=INDIRECT("'["&G322&"]"&E322&"'!"&$AH$2)),INDIRECT("'["&G322&"]"&E322&"'!"&$Y$3),0)} -> #VALUE! | N322: {=IF(AND(G322=INDIRECT("'["&G322&"]"&E322&"'!"&$AH$2),OR(K322=INDIRECT("'["&G322&"]"&E322&"'!"&$Z$2))),INDIRECT("'["&G322&"]"&E322&"'!"&$Z$3),0)} -> #VALUE! | O322: {=IF(AND(G322=INDIRECT("'["&G322&"]"&E322&"'!"&$AH$2),OR(L322=INDIRECT("'["&G322&"]"&E322&"'!"&$AA$2))),INDIRECT("'["&G322&"]"&E322&"'!"&$AA$3),0)} -> #VALUE! | P322: {=IF(AND(G322=INDIRECT("'["&G322&"]"&E322&"'!"&$AH$2),OR(VALUE(I322)=INDIRECT("'["&G322&"]"&E322&"'!"&$AB$2))),INDIRECT("'["&G322&"]"&E322&"'!"&$AB$3),0)} -> #VALUE! | Q322: {=IF(AND(G322=INDIRECT("'["&G322&"]"&E322&"'!"&$AH$2),OR(VALUE(I322)=INDIRECT("'["&G322&"]"&E322&"'!"&$AC$2))),INDIRECT("'["&G322&"]"&E322&"'!"&$AC$3),0)} -> #VALUE! | R322: {=IF(AND(G322=INDIRECT("'["&G322&"]"&E322&"'!"&$AH$2),OR(I322=INDIRECT("'["&G322&"]"&E322&"'!"&$AD$2))),INDIRECT("'["&G322&"]"&E322&"'!"&$AD$3),0)} -> #VALUE! | S322: {=IF(AND(G322=INDIRECT("'["&G322&"]"&E322&"'!"&$AH$2),OR(I322=INDIRECT("'["&G322&"]"&E322&"'!"&$AE$2))),INDIRECT("'["&G322&"]"&E322&"'!"&$AE$3),0)} -> #VALUE! | T322: {=IF(AND(G322=INDIRECT("'["&G322&"]"&E322&"'!"&$AH$2),OR(I322=INDIRECT("'["&G322&"]"&E322&"'!"&$AF$2))),INDIRECT("'["&G322&"]"&E322&"'!"&$AF$3),0)} -> #VALUE! | U322: {=IF(AND(G322=INDIRECT("'["&G322&"]"&E322&"'!"&$AH$2),OR(I322=INDIRECT("'["&G322&"]"&E322&"'!"&$AG$2))),INDIRECT("'["&G322&"]"&E322&"'!"&$AG$3),0)} -> #VALUE! | V322: =MID(B322,7,9) | W322: {=IF(AND(G322=INDIRECT("'["&G322&"]"&E322&"'!"&$AH$2),OR(V322=INDIRECT("'["&G322&"]"&E322&"'!"&$AI$2))),INDIRECT("'["&G322&"]"&E322&"'!"&$AI$3),0)} -> #VALUE! | AJ322: 1 | AK322: =(C322*AJ322%) -> 0 | AL322: =C322-AK322 -> 0 | AM322: =IF(A322<>"",IF(AM322="",NOW(),AM322),"") | AN322: =IF(VALUE(N322),"/","") -> #VALUE! | AO322: =IF(VALUE(O322),"/","") -> #VALUE! | AP322: =IF(ISTEXT(W322),"อายัด","") | AQ322: =IF(AND(C322<>0, C323=0), SUM($C$2:C322)-SUM($AQ$1:AQ321), "") | AR322: =IF(AND(AK322<>0, AK323=0), SUM($AK$2:AK322)-SUM($AR$1:AR321), "")
B323: =LEFT(A323,15) | C323: {=SUM(IF(ISNUMBER(M323:U323),M323:U323,""))} -> 0 | D323: =MID(A323,4,2) | E323: =IF(ISEVEN(D323),D323-1,VALUE(D323)) -> #VALUE! | F323: =LEFT(A323,2) | G323: =CONCATENATE(F323,".xlsx") -> .xlsx | H323: {=IF(AND(VALUE(E323)=INDIRECT("'["&G323&"]"&E323&"'!"&$X$2),G323=INDIRECT("'["&G323&"]"&E323&"'!"&$X$3)),INDIRECT("'["&G323&"]"&E323&"'!"&$X$1),0)} -> #VALUE! | I323: =MID(A323,10,6) | J323: =RIGHT(I323,2) | K323: =LEFT(I323,3) | L323: =RIGHT(I323,3) | M323: {=IF(AND(J323=INDIRECT("'["&G323&"]"&E323&"'!"&$Y$2),G323=INDIRECT("'["&G323&"]"&E323&"'!"&$AH$2)),INDIRECT("'["&G323&"]"&E323&"'!"&$Y$3),0)} -> #VALUE! | N323: {=IF(AND(G323=INDIRECT("'["&G323&"]"&E323&"'!"&$AH$2),OR(K323=INDIRECT("'["&G323&"]"&E323&"'!"&$Z$2))),INDIRECT("'["&G323&"]"&E323&"'!"&$Z$3),0)} -> #VALUE! | O323: {=IF(AND(G323=INDIRECT("'["&G323&"]"&E323&"'!"&$AH$2),OR(L323=INDIRECT("'["&G323&"]"&E323&"'!"&$AA$2))),INDIRECT("'["&G323&"]"&E323&"'!"&$AA$3),0)} -> #VALUE! | P323: {=IF(AND(G323=INDIRECT("'["&G323&"]"&E323&"'!"&$AH$2),OR(VALUE(I323)=INDIRECT("'["&G323&"]"&E323&"'!"&$AB$2))),INDIRECT("'["&G323&"]"&E323&"'!"&$AB$3),0)} -> #VALUE! | Q323: {=IF(AND(G323=INDIRECT("'["&G323&"]"&E323&"'!"&$AH$2),OR(VALUE(I323)=INDIRECT("'["&G323&"]"&E323&"'!"&$AC$2))),INDIRECT("'["&G323&"]"&E323&"'!"&$AC$3),0)} -> #VALUE! | R323: {=IF(AND(G323=INDIRECT("'["&G323&"]"&E323&"'!"&$AH$2),OR(I323=INDIRECT("'["&G323&"]"&E323&"'!"&$AD$2))),INDIRECT("'["&G323&"]"&E323&"'!"&$AD$3),0)} -> #VALUE! | S323: {=IF(AND(G323=INDIRECT("'["&G323&"]"&E323&"'!"&$AH$2),OR(I323=INDIRECT("'["&G323&"]"&E323&"'!"&$AE$2))),INDIRECT("'["&G323&"]"&E323&"'!"&$AE$3),0)} -> #VALUE! | T323: {=IF(AND(G323=INDIRECT("'["&G323&"]"&E323&"'!"&$AH$2),OR(I323=INDIRECT("'["&G323&"]"&E323&"'!"&$AF$2))),INDIRECT("'["&G323&"]"&E323&"'!"&$AF$3),0)} -> #VALUE! | U323: {=IF(AND(G323=INDIRECT("'["&G323&"]"&E323&"'!"&$AH$2),OR(I323=INDIRECT("'["&G323&"]"&E323&"'!"&$AG$2))),INDIRECT("'["&G323&"]"&E323&"'!"&$AG$3),0)} -> #VALUE! | V323: =MID(B323,7,9) | W323: {=IF(AND(G323=INDIRECT("'["&G323&"]"&E323&"'!"&$AH$2),OR(V323=INDIRECT("'["&G323&"]"&E323&"'!"&$AI$2))),INDIRECT("'["&G323&"]"&E323&"'!"&$AI$3),0)} -> #VALUE! | AJ323: 1 | AK323: =(C323*AJ323%) -> 0 | AL323: =C323-AK323 -> 0 | AM323: =IF(A323<>"",IF(AM323="",NOW(),AM323),"") | AN323: =IF(VALUE(N323),"/","") -> #VALUE! | AO323: =IF(VALUE(O323),"/","") -> #VALUE! | AP323: =IF(ISTEXT(W323),"อายัด","") | AQ323: =IF(AND(C323<>0, C324=0), SUM($C$2:C323)-SUM($AQ$1:AQ322), "") | AR323: =IF(AND(AK323<>0, AK324=0), SUM($AK$2:AK323)-SUM($AR$1:AR322), "")
